[19:25:02] [DEBUG] Running client sanity checks...
[19:25:05] [DEBUG] No setup function found in play
[19:25:05] [DEBUG] Found extension class Music in play: Attempting to load
[19:25:05] [DEBUG] Added callback: Music._menu
[19:25:05] [DEBUG] Added callback: Music._pause
[19:25:05] [DEBUG] Added callback: Music._resume
[19:25:05] [DEBUG] Added callback: Music._skip
[19:25:05] [DEBUG] Added callback: Music._stop
[19:25:05] [DEBUG] Added callback: Music.play
[19:25:05] [DEBUG] Loaded Extension: play
[19:25:06] [DEBUG] No setup function found in askgpt
[19:25:06] [DEBUG] Found extension class Gpt in askgpt: Attempting to load
[19:25:06] [DEBUG] Added callback: Gpt._askgpt
[19:25:06] [DEBUG] Added callback: Gpt._img
[19:25:06] [DEBUG] Loaded Extension: askgpt
[19:25:06] [DEBUG] No setup function found in askbard
[19:25:06] [DEBUG] Found extension class Bard in askbard: Attempting to load
[19:25:06] [DEBUG] Added callback: Bard._askbard
[19:25:06] [DEBUG] Added callback: Bard._endbard
[19:25:06] [DEBUG] Loaded Extension: askbard
[19:25:06] [DEBUG] No setup function found in noi_chu
[19:25:06] [DEBUG] Found extension class NoiChu in noi_chu: Attempting to load
[19:25:06] [DEBUG] Added callback: NoiChu._reset
[19:25:06] [DEBUG] Added callback: NoiChu._world_setup
[19:25:06] [DEBUG] Loaded Extension: noi_chu
[19:25:06] [DEBUG] No setup function found in db_refesh
[19:25:06] [DEBUG] Found extension class Database in db_refesh: Attempting to load
[19:25:06] [DEBUG] Added callback: Database.dbv1_command
[19:25:06] [DEBUG] Added callback: Database.dbv2_command
[19:25:06] [DEBUG] Loaded Extension: db_refesh
[19:25:06] [DEBUG] Added callback: ___stop
[19:25:06] [DEBUG] Added callback: __join
[19:25:06] [DEBUG] Added callback: __leave
[19:25:06] [DEBUG] Added callback: _about
[19:25:06] [DEBUG] Added callback: _help
[19:25:06] [DEBUG] Added callback: _record_channel_set
[19:25:06] [DEBUG] Added callback: _refresh
[19:25:06] [DEBUG] Added callback: _setup
[19:25:06] [DEBUG] Added callback: _starup
[19:25:06] [DEBUG] 9 callbacks have been loaded from __main__.
[19:25:06] [DEBUG] Added callback: _disconnect
[19:25:06] [DEBUG] Added callback: _on_websocket_ready
[19:25:06] [DEBUG] Added callback: on_autocomplete_completion
[19:25:06] [DEBUG] Added callback: on_autocomplete_error
[19:25:06] [DEBUG] Added callback: on_command_completion
[19:25:06] [DEBUG] Added callback: on_command_error
[19:25:06] [DEBUG] Added callback: on_component_completion
[19:25:06] [DEBUG] Added callback: on_component_error
[19:25:06] [DEBUG] Added callback: on_error
[19:25:06] [DEBUG] Added callback: on_modal_completion
[19:25:06] [DEBUG] Added callback: on_modal_error
[19:25:06] [DEBUG] Added callback: on_resume
[19:25:06] [DEBUG] 12 callbacks have been loaded from Client.
[19:25:06] [DEBUG] Attempting to login
[19:25:07] [DEBUG] Caching ingested rate limit data for: f7ead6a7674e5a323d93786263b66cb1
[19:25:07] [DEBUG] GET /users/@me Received 200 :: [49/50 calls remaining]
[19:25:07] [DEBUG] Caching ingested rate limit data for: f7ead6a7674e5a323d93786263b66cb1
[19:25:07] [DEBUG] GET /oauth2/applications/@me Received 200 :: [49/50 calls remaining]
[19:25:07] [DEBUG] Caching ingested rate limit data for: f7ead6a7674e5a323d93786263b66cb1
[19:25:07] [DEBUG] GET /gateway Received 200 :: [49/50 calls remaining]
[19:25:07] [INFO] Shard ID 0 | Starting Shard
[19:25:07] [INFO] Shard ID 0 | Shard is attempting to connect to gateway...
[19:25:08] [DEBUG] Shard ID 0 | Identification payload sent to gateway, requesting intents: 3407613
[19:25:08] [INFO] Shard ID 0 | Gateway connection established
[19:25:08] [DEBUG] Shard ID 0 | Session ID: 2c949591d082f002116fbe04f28f589f Trace: ['["gateway-prd-us-east1-c-9rhl",{"micros":124141,"calls":["id_created",{"micros":1420,"calls":[]},"session_lookup_time",{"micros":2821,"calls":[]},"session_lookup_finished",{"micros":21,"calls":[]},"discord-sessions-prd-2-215",{"micros":119125,"calls":["start_session",{"micros":46734,"calls":["discord-api-5b464978d4-zx2sm",{"micros":41480,"calls":["get_user",{"micros":7432},"get_guilds",{"micros":3408},"send_scheduled_deletion_message",{"micros":10},"guild_join_requests",{"micros":945},"authorized_ip_coro",{"micros":10}]}]},"starting_guild_connect",{"micros":73,"calls":[]},"presence_started",{"micros":430,"calls":[]},"guilds_started",{"micros":171,"calls":[]},"guilds_connect",{"micros":2,"calls":[]},"presence_connect",{"micros":71685,"calls":[]},"connect_finished",{"micros":71692,"calls":[]},"build_ready",{"micros":21,"calls":[]},"clean_ready",{"micros":1,"calls":[]},"optimize_ready",{"micros":1,"calls":[]},"split_ready",{"micros":0,"calls":[]}]}]}]']
[19:25:08] [DEBUG] Dispatching Event: websocket_ready
[19:25:08] [DEBUG] Caching ingested rate limit data for: f7ead6a7674e5a323d93786263b66cb1
[19:25:08] [DEBUG] GET /applications/{application_id}/commands Received 200 :: [49/50 calls remaining]
[19:25:09] [DEBUG] Caching ingested rate limit data for: f7ead6a7674e5a323d93786263b66cb1
[19:25:09] [DEBUG] GET /applications/{application_id}/commands Received 200 :: [49/50 calls remaining]
[19:25:09] [DEBUG] 0 is already up-to-date with 19 commands.
[19:25:09] [DEBUG] Sync of 1 scopes took 0.6073706999999899 seconds
[19:25:09] [DEBUG] Dispatching Event: startup
[19:25:09] [DEBUG] Sending data to websocket: {"op": 3, "d": {"since": 1700828709061, "activities": [{"name": "l\u1ec7nh /help \u0111\u1ec3 gi\u00fap \u0111\u1ee1", "type": 0}], "status": "idle", "afk": false}}
[19:25:19] [DEBUG] 1177583910310379550::set_record should be called
[19:25:21] [DEBUG] Dispatching Event: command_error
[19:25:21] [DEBUG] Dispatching Event: command_completion
[19:25:21] [DEBUG] Dispatching Event: error
[19:25:21] [INFO] Command Called: set_record with event.ctx.args = [GuildVoice(id=1159832166998487054, name='Chung', type=<ChannelType.GUILD_VOICE: 2>)] | event.ctx.kwargs = {'channel': GuildVoice(id=1159832166998487054, name='Chung', type=<ChannelType.GUILD_VOICE: 2>)}
[19:25:21] [ERROR] Ignoring exception in cmd `/set_record`:
Traceback (most recent call last):
  File "C:\Users\huuti\AppData\Local\Programs\Python\Python311\Lib\site-packages\pymysql\connections.py", line 644, in connect
    sock = socket.create_connection(
           ^^^^^^^^^^^^^^^^^^^^^^^^^
  File "C:\Users\huuti\AppData\Local\Programs\Python\Python311\Lib\socket.py", line 851, in create_connection
    raise exceptions[0]
  File "C:\Users\huuti\AppData\Local\Programs\Python\Python311\Lib\socket.py", line 836, in create_connection
    sock.connect(sa)
ConnectionRefusedError: [WinError 10061] No connection could be made because the target machine actively refused it

During handling of the above exception, another exception occurred:

Traceback (most recent call last):
  File "C:\Users\huuti\AppData\Local\Programs\Python\Python311\Lib\site-packages\interactions\client\client.py", line 1900, in __dispatch_interaction
    response = await callback
               ^^^^^^^^^^^^^^
  File "C:\Users\huuti\AppData\Local\Programs\Python\Python311\Lib\site-packages\interactions\client\client.py", line 1771, in _run_slash_command
    return await command(ctx, **ctx.kwargs)
           ^^^^^^^^^^^^^^^^^^^^^^^^^^^^^^^^
  File "C:\Users\huuti\AppData\Local\Programs\Python\Python311\Lib\site-packages\interactions\models\internal\command.py", line 132, in __call__
    await self.call_callback(self.callback, context)
  File "C:\Users\huuti\AppData\Local\Programs\Python\Python311\Lib\site-packages\interactions\models\internal\application_commands.py", line 833, in call_callback
    return await self.call_with_binding(callback, ctx, *new_args, **new_kwargs)
           ^^^^^^^^^^^^^^^^^^^^^^^^^^^^^^^^^^^^^^^^^^^^^^^^^^^^^^^^^^^^^^^^^^^^
  File "C:\Users\huuti\AppData\Local\Programs\Python\Python311\Lib\site-packages\interactions\models\internal\callback.py", line 43, in call_with_binding
    return await callback(*args, **kwargs)
           ^^^^^^^^^^^^^^^^^^^^^^^^^^^^^^^
  File "D:\Project\Python\qpneruy-Git\music\Main.py", line 195, in _record_channel_set
    with pymysql.connect(host='127.0.0.1', user='root', password='', database='discord_voice') as connect_thread:
         ^^^^^^^^^^^^^^^^^^^^^^^^^^^^^^^^^^^^^^^^^^^^^^^^^^^^^^^^^^^^^^^^^^^^^^^^^^^^^^^^^^^^^
  File "C:\Users\huuti\AppData\Local\Programs\Python\Python311\Lib\site-packages\pymysql\connections.py", line 358, in __init__
    self.connect()
  File "C:\Users\huuti\AppData\Local\Programs\Python\Python311\Lib\site-packages\pymysql\connections.py", line 711, in connect
    raise exc
pymysql.err.OperationalError: (2003, "Can't connect to MySQL server on '127.0.0.1' ([WinError 10061] No connection could be made because the target machine actively refused it)")

[19:25:28] [DEBUG] Sending heartbeat every 41.25 seconds
[19:25:28] [DEBUG] Sending data to websocket: {"op": 1, "d": 7}
[19:25:28] [DEBUG] Shard ID 0 | ❤ Gateway is sending a Heartbeat
[19:25:28] [DEBUG] Shard ID 0 | ❤ Received heartbeat acknowledgement from gateway
[19:25:35] [DEBUG] 1177583910310379550::set_record should be called
[19:25:35] [DEBUG] Dispatching Event: command_error
[19:25:35] [DEBUG] Dispatching Event: command_completion
[19:25:35] [DEBUG] Dispatching Event: error
[19:25:35] [INFO] Command Called: set_record with event.ctx.args = [GuildVoice(id=1159832166998487054, name='Chung', type=<ChannelType.GUILD_VOICE: 2>)] | event.ctx.kwargs = {'channel': GuildVoice(id=1159832166998487054, name='Chung', type=<ChannelType.GUILD_VOICE: 2>)}
[19:25:35] [ERROR] Ignoring exception in cmd `/set_record`:
Traceback (most recent call last):
  File "C:\Users\huuti\AppData\Local\Programs\Python\Python311\Lib\site-packages\interactions\client\client.py", line 1900, in __dispatch_interaction
    response = await callback
               ^^^^^^^^^^^^^^
  File "C:\Users\huuti\AppData\Local\Programs\Python\Python311\Lib\site-packages\interactions\client\client.py", line 1771, in _run_slash_command
    return await command(ctx, **ctx.kwargs)
           ^^^^^^^^^^^^^^^^^^^^^^^^^^^^^^^^
  File "C:\Users\huuti\AppData\Local\Programs\Python\Python311\Lib\site-packages\interactions\models\internal\command.py", line 132, in __call__
    await self.call_callback(self.callback, context)
  File "C:\Users\huuti\AppData\Local\Programs\Python\Python311\Lib\site-packages\interactions\models\internal\application_commands.py", line 833, in call_callback
    return await self.call_with_binding(callback, ctx, *new_args, **new_kwargs)
           ^^^^^^^^^^^^^^^^^^^^^^^^^^^^^^^^^^^^^^^^^^^^^^^^^^^^^^^^^^^^^^^^^^^^
  File "C:\Users\huuti\AppData\Local\Programs\Python\Python311\Lib\site-packages\interactions\models\internal\callback.py", line 43, in call_with_binding
    return await callback(*args, **kwargs)
           ^^^^^^^^^^^^^^^^^^^^^^^^^^^^^^^
  File "D:\Project\Python\qpneruy-Git\music\Main.py", line 200, in _record_channel_set
    cursor.execute(select_query)
  File "C:\Users\huuti\AppData\Local\Programs\Python\Python311\Lib\site-packages\pymysql\cursors.py", line 153, in execute
    result = self._query(query)
             ^^^^^^^^^^^^^^^^^^
  File "C:\Users\huuti\AppData\Local\Programs\Python\Python311\Lib\site-packages\pymysql\cursors.py", line 322, in _query
    conn.query(q)
  File "C:\Users\huuti\AppData\Local\Programs\Python\Python311\Lib\site-packages\pymysql\connections.py", line 558, in query
    self._affected_rows = self._read_query_result(unbuffered=unbuffered)
                          ^^^^^^^^^^^^^^^^^^^^^^^^^^^^^^^^^^^^^^^^^^^^^^
  File "C:\Users\huuti\AppData\Local\Programs\Python\Python311\Lib\site-packages\pymysql\connections.py", line 822, in _read_query_result
    result.read()
  File "C:\Users\huuti\AppData\Local\Programs\Python\Python311\Lib\site-packages\pymysql\connections.py", line 1200, in read
    first_packet = self.connection._read_packet()
                   ^^^^^^^^^^^^^^^^^^^^^^^^^^^^^^
  File "C:\Users\huuti\AppData\Local\Programs\Python\Python311\Lib\site-packages\pymysql\connections.py", line 772, in _read_packet
    packet.raise_for_error()
  File "C:\Users\huuti\AppData\Local\Programs\Python\Python311\Lib\site-packages\pymysql\protocol.py", line 221, in raise_for_error
    err.raise_mysql_exception(self._data)
  File "C:\Users\huuti\AppData\Local\Programs\Python\Python311\Lib\site-packages\pymysql\err.py", line 143, in raise_mysql_exception
    raise errorclass(errno, errval)
pymysql.err.ProgrammingError: (1064, "You have an error in your SQL syntax; check the manual that corresponds to your MariaDB server version for the right syntax to use near 'SELECT * FROM server_data WHERE ten_server = 1159832166998487050' at line 1")

[19:26:09] [DEBUG] Sending data to websocket: {"op": 1, "d": 8}
[19:26:09] [DEBUG] Shard ID 0 | ❤ Gateway is sending a Heartbeat
[19:26:10] [DEBUG] Shard ID 0 | ❤ Received heartbeat acknowledgement from gateway
[19:26:39] [DEBUG] Dispatching Event: disconnect
[19:26:39] [DEBUG] Stopping the bot.
[19:26:39] [INFO] Shard ID 0 | Stopping Shard
[19:26:39] [DEBUG] Stopping the bot.
[19:26:39] [INFO] Shard ID 0 | Stopping Shard
