[18:18:41] [DEBUG] Running client sanity checks...
[18:18:42] [DEBUG] No setup function found in play
[18:18:42] [DEBUG] Found extension class Music in play: Attempting to load
[18:18:42] [DEBUG] Added callback: Music._menu
[18:18:42] [DEBUG] Added callback: Music._pause
[18:18:42] [DEBUG] Added callback: Music._resume
[18:18:42] [DEBUG] Added callback: Music._skip
[18:18:42] [DEBUG] Added callback: Music._stop
[18:18:42] [DEBUG] Added callback: Music.play
[18:18:42] [DEBUG] Loaded Extension: play
[18:18:43] [DEBUG] No setup function found in askbard
[18:18:43] [DEBUG] Found extension class Bard in askbard: Attempting to load
[18:18:43] [DEBUG] Added callback: Bard._askbard
[18:18:43] [DEBUG] Added callback: Bard._endbard
[18:18:43] [DEBUG] Added callback: Bard.set_bard_channel
[18:18:43] [DEBUG] Loaded Extension: askbard
[18:18:43] [DEBUG] No setup function found in noi_chu
[18:18:43] [DEBUG] Found extension class NoiChu in noi_chu: Attempting to load
[18:18:43] [DEBUG] Added callback: NoiChu._reset
[18:18:43] [DEBUG] Added callback: NoiChu._world_setup
[18:18:43] [DEBUG] Loaded Extension: noi_chu
[18:18:43] [DEBUG] No setup function found in db_refesh
[18:18:43] [DEBUG] Found extension class Database in db_refesh: Attempting to load
[18:18:43] [DEBUG] Loaded Extension: db_refesh
[18:18:43] [DEBUG] Added callback: __join
[18:18:43] [DEBUG] Added callback: __leave
[18:18:43] [DEBUG] Added callback: _about
[18:18:43] [DEBUG] Added callback: _help
[18:18:43] [DEBUG] Added callback: _refresh
[18:18:43] [DEBUG] Added callback: _setup
[18:18:43] [DEBUG] Added callback: _starup
[18:18:43] [DEBUG] 7 callbacks have been loaded from __main__.
[18:18:43] [DEBUG] Added callback: _disconnect
[18:18:43] [DEBUG] Added callback: _on_websocket_ready
[18:18:43] [DEBUG] Added callback: on_autocomplete_completion
[18:18:43] [DEBUG] Added callback: on_autocomplete_error
[18:18:43] [DEBUG] Added callback: on_command_completion
[18:18:43] [DEBUG] Added callback: on_command_error
[18:18:43] [DEBUG] Added callback: on_component_completion
[18:18:43] [DEBUG] Added callback: on_component_error
[18:18:43] [DEBUG] Added callback: on_error
[18:18:43] [DEBUG] Added callback: on_modal_completion
[18:18:43] [DEBUG] Added callback: on_modal_error
[18:18:43] [DEBUG] Added callback: on_resume
[18:18:43] [DEBUG] 12 callbacks have been loaded from Client.
[18:18:43] [DEBUG] Attempting to login
[18:18:43] [DEBUG] Caching ingested rate limit data for: 78bb8553d9352a5a2f89f9def401287a
[18:18:43] [DEBUG] GET /users/@me Has exhausted its ratelimit (1000)! Locking route for 0.001 seconds
[18:18:43] [DEBUG] GET /users/@me Received 200 :: [0/1000 calls remaining]
[18:18:44] [DEBUG] Caching ingested rate limit data for: d28a133af187e91d71d96a223467ce49
[18:18:44] [DEBUG] GET /oauth2/applications/@me Has exhausted its ratelimit (1000)! Locking route for 0.001 seconds
[18:18:44] [DEBUG] GET /oauth2/applications/@me Received 200 :: [0/1000 calls remaining]
[18:18:44] [DEBUG] Caching ingested rate limit data for: 0a6d458104b103c7be293cc9b284d9ee
[18:18:44] [DEBUG] GET /gateway Received 200 :: [99/100 calls remaining]
[18:18:44] [INFO] Shard ID 0 | Starting Shard
[18:18:44] [INFO] Shard ID 0 | Shard is attempting to connect to gateway...
[18:18:44] [DEBUG] Shard ID 0 | Identification payload sent to gateway, requesting intents: 3407613
[18:18:45] [INFO] Shard ID 0 | Gateway connection established
[18:18:45] [DEBUG] Shard ID 0 | Session ID: 03e8744410b15c661cb2aa6bdd5c5915 Trace: ['["gateway-prd-us-east1-c-2wgk",{"micros":137086,"calls":["id_created",{"micros":1144,"calls":[]},"session_lookup_time",{"micros":270,"calls":[]},"session_lookup_finished",{"micros":12,"calls":[]},"discord-sessions-prd-2-65",{"micros":134415,"calls":["start_session",{"micros":97826,"calls":["discord-api-f65587479-mjf2j",{"micros":90168,"calls":["get_user",{"micros":33625},"get_guilds",{"micros":9920},"send_scheduled_deletion_message",{"micros":10},"guild_join_requests",{"micros":540},"authorized_ip_coro",{"micros":12}]}]},"starting_guild_connect",{"micros":72,"calls":[]},"presence_started",{"micros":293,"calls":[]},"guilds_started",{"micros":170,"calls":[]},"guilds_connect",{"micros":2,"calls":[]},"presence_connect",{"micros":36024,"calls":[]},"connect_finished",{"micros":36030,"calls":[]},"build_ready",{"micros":21,"calls":[]},"clean_ready",{"micros":1,"calls":[]},"optimize_ready",{"micros":0,"calls":[]},"split_ready",{"micros":1,"calls":[]}]}]}]']
[18:18:45] [DEBUG] Dispatching Event: websocket_ready
[18:18:45] [DEBUG] Dispatching Event: guild_join
[18:18:45] [DEBUG] Dispatching Event: error
[18:18:45] [ERROR] Ignoring exception in GuildJoin():
Traceback (most recent call last):
  File "C:\Users\huuti\AppData\Local\Programs\Python\Python311\Lib\site-packages\interactions\client\client.py", line 607, in _async_wrap
    await _coro(_event, *_args, **_kwargs)
  File "C:\Users\huuti\AppData\Local\Programs\Python\Python311\Lib\site-packages\interactions\models\internal\callback.py", line 31, in __call__
    return await self.callback(self._binding, *args, **kwargs)
           ^^^^^^^^^^^^^^^^^^^^^^^^^^^^^^^^^^^^^^^^^^^^^^^^^^^
  File "D:\Project\Python\qpneruy-Git\music\db_refesh.py", line 62, in _on_guild_join
    cursor.execute(insert_data_query, new_data)
  File "C:\Users\huuti\AppData\Local\Programs\Python\Python311\Lib\site-packages\pymysql\cursors.py", line 153, in execute
    result = self._query(query)
             ^^^^^^^^^^^^^^^^^^
  File "C:\Users\huuti\AppData\Local\Programs\Python\Python311\Lib\site-packages\pymysql\cursors.py", line 322, in _query
    conn.query(q)
  File "C:\Users\huuti\AppData\Local\Programs\Python\Python311\Lib\site-packages\pymysql\connections.py", line 558, in query
    self._affected_rows = self._read_query_result(unbuffered=unbuffered)
                          ^^^^^^^^^^^^^^^^^^^^^^^^^^^^^^^^^^^^^^^^^^^^^^
  File "C:\Users\huuti\AppData\Local\Programs\Python\Python311\Lib\site-packages\pymysql\connections.py", line 822, in _read_query_result
    result.read()
  File "C:\Users\huuti\AppData\Local\Programs\Python\Python311\Lib\site-packages\pymysql\connections.py", line 1200, in read
    first_packet = self.connection._read_packet()
                   ^^^^^^^^^^^^^^^^^^^^^^^^^^^^^^
  File "C:\Users\huuti\AppData\Local\Programs\Python\Python311\Lib\site-packages\pymysql\connections.py", line 772, in _read_packet
    packet.raise_for_error()
  File "C:\Users\huuti\AppData\Local\Programs\Python\Python311\Lib\site-packages\pymysql\protocol.py", line 221, in raise_for_error
    err.raise_mysql_exception(self._data)
  File "C:\Users\huuti\AppData\Local\Programs\Python\Python311\Lib\site-packages\pymysql\err.py", line 143, in raise_mysql_exception
    raise errorclass(errno, errval)
pymysql.err.DataError: (1366, "Incorrect integer value: 'NULL' for column `discord_voice`.`server_data`.`record_state` at row 1")

[18:18:45] [DEBUG] Dispatching Event: guild_join
[18:18:45] [DEBUG] Dispatching Event: error
[18:18:45] [ERROR] Ignoring exception in GuildJoin():
Traceback (most recent call last):
  File "C:\Users\huuti\AppData\Local\Programs\Python\Python311\Lib\site-packages\interactions\client\client.py", line 607, in _async_wrap
    await _coro(_event, *_args, **_kwargs)
  File "C:\Users\huuti\AppData\Local\Programs\Python\Python311\Lib\site-packages\interactions\models\internal\callback.py", line 31, in __call__
    return await self.callback(self._binding, *args, **kwargs)
           ^^^^^^^^^^^^^^^^^^^^^^^^^^^^^^^^^^^^^^^^^^^^^^^^^^^
  File "D:\Project\Python\qpneruy-Git\music\db_refesh.py", line 62, in _on_guild_join
    cursor.execute(insert_data_query, new_data)
  File "C:\Users\huuti\AppData\Local\Programs\Python\Python311\Lib\site-packages\pymysql\cursors.py", line 153, in execute
    result = self._query(query)
             ^^^^^^^^^^^^^^^^^^
  File "C:\Users\huuti\AppData\Local\Programs\Python\Python311\Lib\site-packages\pymysql\cursors.py", line 322, in _query
    conn.query(q)
  File "C:\Users\huuti\AppData\Local\Programs\Python\Python311\Lib\site-packages\pymysql\connections.py", line 558, in query
    self._affected_rows = self._read_query_result(unbuffered=unbuffered)
                          ^^^^^^^^^^^^^^^^^^^^^^^^^^^^^^^^^^^^^^^^^^^^^^
  File "C:\Users\huuti\AppData\Local\Programs\Python\Python311\Lib\site-packages\pymysql\connections.py", line 822, in _read_query_result
    result.read()
  File "C:\Users\huuti\AppData\Local\Programs\Python\Python311\Lib\site-packages\pymysql\connections.py", line 1200, in read
    first_packet = self.connection._read_packet()
                   ^^^^^^^^^^^^^^^^^^^^^^^^^^^^^^
  File "C:\Users\huuti\AppData\Local\Programs\Python\Python311\Lib\site-packages\pymysql\connections.py", line 772, in _read_packet
    packet.raise_for_error()
  File "C:\Users\huuti\AppData\Local\Programs\Python\Python311\Lib\site-packages\pymysql\protocol.py", line 221, in raise_for_error
    err.raise_mysql_exception(self._data)
  File "C:\Users\huuti\AppData\Local\Programs\Python\Python311\Lib\site-packages\pymysql\err.py", line 143, in raise_mysql_exception
    raise errorclass(errno, errval)
pymysql.err.DataError: (1366, "Incorrect integer value: 'NULL' for column `discord_voice`.`server_data`.`record_state` at row 1")

[18:18:45] [DEBUG] Dispatching Event: guild_join
[18:18:45] [DEBUG] Dispatching Event: error
[18:18:45] [ERROR] Ignoring exception in GuildJoin():
Traceback (most recent call last):
  File "C:\Users\huuti\AppData\Local\Programs\Python\Python311\Lib\site-packages\interactions\client\client.py", line 607, in _async_wrap
    await _coro(_event, *_args, **_kwargs)
  File "C:\Users\huuti\AppData\Local\Programs\Python\Python311\Lib\site-packages\interactions\models\internal\callback.py", line 31, in __call__
    return await self.callback(self._binding, *args, **kwargs)
           ^^^^^^^^^^^^^^^^^^^^^^^^^^^^^^^^^^^^^^^^^^^^^^^^^^^
  File "D:\Project\Python\qpneruy-Git\music\db_refesh.py", line 62, in _on_guild_join
    cursor.execute(insert_data_query, new_data)
  File "C:\Users\huuti\AppData\Local\Programs\Python\Python311\Lib\site-packages\pymysql\cursors.py", line 153, in execute
    result = self._query(query)
             ^^^^^^^^^^^^^^^^^^
  File "C:\Users\huuti\AppData\Local\Programs\Python\Python311\Lib\site-packages\pymysql\cursors.py", line 322, in _query
    conn.query(q)
  File "C:\Users\huuti\AppData\Local\Programs\Python\Python311\Lib\site-packages\pymysql\connections.py", line 558, in query
    self._affected_rows = self._read_query_result(unbuffered=unbuffered)
                          ^^^^^^^^^^^^^^^^^^^^^^^^^^^^^^^^^^^^^^^^^^^^^^
  File "C:\Users\huuti\AppData\Local\Programs\Python\Python311\Lib\site-packages\pymysql\connections.py", line 822, in _read_query_result
    result.read()
  File "C:\Users\huuti\AppData\Local\Programs\Python\Python311\Lib\site-packages\pymysql\connections.py", line 1200, in read
    first_packet = self.connection._read_packet()
                   ^^^^^^^^^^^^^^^^^^^^^^^^^^^^^^
  File "C:\Users\huuti\AppData\Local\Programs\Python\Python311\Lib\site-packages\pymysql\connections.py", line 772, in _read_packet
    packet.raise_for_error()
  File "C:\Users\huuti\AppData\Local\Programs\Python\Python311\Lib\site-packages\pymysql\protocol.py", line 221, in raise_for_error
    err.raise_mysql_exception(self._data)
  File "C:\Users\huuti\AppData\Local\Programs\Python\Python311\Lib\site-packages\pymysql\err.py", line 143, in raise_mysql_exception
    raise errorclass(errno, errval)
pymysql.err.DataError: (1366, "Incorrect integer value: 'NULL' for column `discord_voice`.`server_data`.`record_state` at row 1")

[18:18:45] [DEBUG] Dispatching Event: guild_join
[18:18:45] [DEBUG] Dispatching Event: error
[18:18:45] [ERROR] Ignoring exception in GuildJoin():
Traceback (most recent call last):
  File "C:\Users\huuti\AppData\Local\Programs\Python\Python311\Lib\site-packages\interactions\client\client.py", line 607, in _async_wrap
    await _coro(_event, *_args, **_kwargs)
  File "C:\Users\huuti\AppData\Local\Programs\Python\Python311\Lib\site-packages\interactions\models\internal\callback.py", line 31, in __call__
    return await self.callback(self._binding, *args, **kwargs)
           ^^^^^^^^^^^^^^^^^^^^^^^^^^^^^^^^^^^^^^^^^^^^^^^^^^^
  File "D:\Project\Python\qpneruy-Git\music\db_refesh.py", line 62, in _on_guild_join
    cursor.execute(insert_data_query, new_data)
  File "C:\Users\huuti\AppData\Local\Programs\Python\Python311\Lib\site-packages\pymysql\cursors.py", line 153, in execute
    result = self._query(query)
             ^^^^^^^^^^^^^^^^^^
  File "C:\Users\huuti\AppData\Local\Programs\Python\Python311\Lib\site-packages\pymysql\cursors.py", line 322, in _query
    conn.query(q)
  File "C:\Users\huuti\AppData\Local\Programs\Python\Python311\Lib\site-packages\pymysql\connections.py", line 558, in query
    self._affected_rows = self._read_query_result(unbuffered=unbuffered)
                          ^^^^^^^^^^^^^^^^^^^^^^^^^^^^^^^^^^^^^^^^^^^^^^
  File "C:\Users\huuti\AppData\Local\Programs\Python\Python311\Lib\site-packages\pymysql\connections.py", line 822, in _read_query_result
    result.read()
  File "C:\Users\huuti\AppData\Local\Programs\Python\Python311\Lib\site-packages\pymysql\connections.py", line 1200, in read
    first_packet = self.connection._read_packet()
                   ^^^^^^^^^^^^^^^^^^^^^^^^^^^^^^
  File "C:\Users\huuti\AppData\Local\Programs\Python\Python311\Lib\site-packages\pymysql\connections.py", line 772, in _read_packet
    packet.raise_for_error()
  File "C:\Users\huuti\AppData\Local\Programs\Python\Python311\Lib\site-packages\pymysql\protocol.py", line 221, in raise_for_error
    err.raise_mysql_exception(self._data)
  File "C:\Users\huuti\AppData\Local\Programs\Python\Python311\Lib\site-packages\pymysql\err.py", line 143, in raise_mysql_exception
    raise errorclass(errno, errval)
pymysql.err.DataError: (1366, "Incorrect integer value: 'NULL' for column `discord_voice`.`server_data`.`record_state` at row 1")

[18:18:45] [DEBUG] Dispatching Event: guild_join
[18:18:45] [DEBUG] Dispatching Event: error
[18:18:45] [ERROR] Ignoring exception in GuildJoin():
Traceback (most recent call last):
  File "C:\Users\huuti\AppData\Local\Programs\Python\Python311\Lib\site-packages\interactions\client\client.py", line 607, in _async_wrap
    await _coro(_event, *_args, **_kwargs)
  File "C:\Users\huuti\AppData\Local\Programs\Python\Python311\Lib\site-packages\interactions\models\internal\callback.py", line 31, in __call__
    return await self.callback(self._binding, *args, **kwargs)
           ^^^^^^^^^^^^^^^^^^^^^^^^^^^^^^^^^^^^^^^^^^^^^^^^^^^
  File "D:\Project\Python\qpneruy-Git\music\db_refesh.py", line 62, in _on_guild_join
    cursor.execute(insert_data_query, new_data)
  File "C:\Users\huuti\AppData\Local\Programs\Python\Python311\Lib\site-packages\pymysql\cursors.py", line 153, in execute
    result = self._query(query)
             ^^^^^^^^^^^^^^^^^^
  File "C:\Users\huuti\AppData\Local\Programs\Python\Python311\Lib\site-packages\pymysql\cursors.py", line 322, in _query
    conn.query(q)
  File "C:\Users\huuti\AppData\Local\Programs\Python\Python311\Lib\site-packages\pymysql\connections.py", line 558, in query
    self._affected_rows = self._read_query_result(unbuffered=unbuffered)
                          ^^^^^^^^^^^^^^^^^^^^^^^^^^^^^^^^^^^^^^^^^^^^^^
  File "C:\Users\huuti\AppData\Local\Programs\Python\Python311\Lib\site-packages\pymysql\connections.py", line 822, in _read_query_result
    result.read()
  File "C:\Users\huuti\AppData\Local\Programs\Python\Python311\Lib\site-packages\pymysql\connections.py", line 1200, in read
    first_packet = self.connection._read_packet()
                   ^^^^^^^^^^^^^^^^^^^^^^^^^^^^^^
  File "C:\Users\huuti\AppData\Local\Programs\Python\Python311\Lib\site-packages\pymysql\connections.py", line 772, in _read_packet
    packet.raise_for_error()
  File "C:\Users\huuti\AppData\Local\Programs\Python\Python311\Lib\site-packages\pymysql\protocol.py", line 221, in raise_for_error
    err.raise_mysql_exception(self._data)
  File "C:\Users\huuti\AppData\Local\Programs\Python\Python311\Lib\site-packages\pymysql\err.py", line 143, in raise_mysql_exception
    raise errorclass(errno, errval)
pymysql.err.DataError: (1366, "Incorrect integer value: 'NULL' for column `discord_voice`.`server_data`.`record_state` at row 1")

[18:18:45] [DEBUG] Caching ingested rate limit data for: dd84d9818020c27975c0d5ab4a794d44
[18:18:45] [DEBUG] GET /applications/{application_id}/commands Has exhausted its ratelimit (1000)! Locking route for 0.001 seconds
[18:18:45] [DEBUG] GET /applications/{application_id}/commands Received 200 :: [0/1000 calls remaining]
[18:18:45] [DEBUG] Waiting for bucket dd84d9818020c27975c0d5ab4a794d44 to unlock.
[18:18:46] [DEBUG] Caching ingested rate limit data for: dd84d9818020c27975c0d5ab4a794d44
[18:18:46] [DEBUG] GET /applications/{application_id}/commands Has exhausted its ratelimit (1000)! Locking route for 0.001 seconds
[18:18:46] [DEBUG] GET /applications/{application_id}/commands Received 200 :: [0/1000 calls remaining]
[18:18:46] [INFO] Overwriting 0 with 15 application commands
[18:18:46] [DEBUG] Caching ingested rate limit data for: 3e32a240d3716487d7d8f6dae6c54f6b
[18:18:46] [DEBUG] PUT /applications/{app_id}/commands Received 200 :: [1/2 calls remaining]
[18:18:46] [DEBUG] Sync of 1 scopes took 1.1630982999922708 seconds
[18:18:46] [DEBUG] Dispatching Event: startup
[18:18:46] [DEBUG] Sending data to websocket: {"op": 3, "d": {"since": 1702034326539, "activities": [{"name": "l\u1ec7nh /help \u0111\u1ec3 gi\u00fap \u0111\u1ee1", "type": 0}], "status": "idle", "afk": false}}
[18:19:00] [DEBUG] Sending heartbeat every 41.25 seconds
[18:19:00] [DEBUG] Sending data to websocket: {"op": 1, "d": 6}
[18:19:00] [DEBUG] Shard ID 0 | ❤ Gateway is sending a Heartbeat
[18:19:00] [DEBUG] Shard ID 0 | ❤ Received heartbeat acknowledgement from gateway
[18:19:41] [DEBUG] Sending data to websocket: {"op": 1, "d": 6}
[18:19:41] [DEBUG] Shard ID 0 | ❤ Gateway is sending a Heartbeat
[18:19:42] [DEBUG] Shard ID 0 | ❤ Received heartbeat acknowledgement from gateway
[18:19:51] [DEBUG] Dispatching Event: disconnect
[18:19:51] [DEBUG] Stopping the bot.
[18:19:51] [INFO] Shard ID 0 | Stopping Shard
