[12:01:04] [DEBUG] Running client sanity checks...
[12:01:04] [DEBUG] Loaded Extension: interactions.ext.jurigged
[12:01:06] [DEBUG] No setup function found in play
[12:01:06] [DEBUG] Found extension class Music in play: Attempting to load
[12:01:06] [DEBUG] Added callback: Music._menu
[12:01:06] [DEBUG] Added callback: Music._pause
[12:01:06] [DEBUG] Added callback: Music._resume
[12:01:06] [DEBUG] Added callback: Music._skip
[12:01:06] [DEBUG] Added callback: Music._stop
[12:01:06] [DEBUG] Added callback: Music.play
[12:01:06] [DEBUG] Loaded Extension: play
[12:01:06] [DEBUG] No setup function found in askbard
[12:01:06] [DEBUG] Found extension class Bard in askbard: Attempting to load
[12:01:06] [DEBUG] Added callback: Bard._askbard
[12:01:06] [DEBUG] Added callback: Bard._endbard
[12:01:06] [DEBUG] Added callback: Bard.set_bard_channel
[12:01:06] [DEBUG] Loaded Extension: askbard
[12:01:06] [DEBUG] No setup function found in noi_chu
[12:01:06] [DEBUG] Found extension class NoiChu in noi_chu: Attempting to load
[12:01:06] [DEBUG] Added callback: NoiChu._reset
[12:01:06] [DEBUG] Added callback: NoiChu._world_setup
[12:01:06] [DEBUG] Loaded Extension: noi_chu
[12:01:06] [DEBUG] No setup function found in db_refesh
[12:01:06] [DEBUG] Found extension class Database in db_refesh: Attempting to load
[12:01:06] [DEBUG] Loaded Extension: db_refesh
[12:01:06] [DEBUG] No setup function found in help
[12:01:06] [DEBUG] Found extension class Help in help: Attempting to load
[12:01:06] [DEBUG] Added callback: Help.help
[12:01:06] [DEBUG] Loaded Extension: help
[12:01:06] [DEBUG] Added callback: __join
[12:01:06] [DEBUG] Added callback: __leave
[12:01:06] [DEBUG] Added callback: _about
[12:01:06] [DEBUG] Added callback: _setup
[12:01:06] [DEBUG] Added callback: on_start
[12:01:06] [DEBUG] 5 callbacks have been loaded from __main__.
[12:01:06] [DEBUG] Added callback: _disconnect
[12:01:06] [DEBUG] Added callback: _on_websocket_ready
[12:01:06] [DEBUG] Added callback: on_autocomplete_completion
[12:01:06] [DEBUG] Added callback: on_autocomplete_error
[12:01:06] [DEBUG] Added callback: on_command_completion
[12:01:06] [DEBUG] Added callback: on_command_error
[12:01:06] [DEBUG] Added callback: on_component_completion
[12:01:06] [DEBUG] Added callback: on_component_error
[12:01:06] [DEBUG] Added callback: on_error
[12:01:06] [DEBUG] Added callback: on_modal_completion
[12:01:06] [DEBUG] Added callback: on_modal_error
[12:01:06] [DEBUG] Added callback: on_resume
[12:01:06] [DEBUG] 12 callbacks have been loaded from Client.
[12:01:06] [DEBUG] Attempting to login
[12:01:07] [DEBUG] Caching ingested rate limit data for: 78bb8553d9352a5a2f89f9def401287a
[12:01:07] [DEBUG] GET /users/@me Has exhausted its ratelimit (1000)! Locking route for 0.001 seconds
[12:01:07] [DEBUG] GET /users/@me Received 200 :: [0/1000 calls remaining]
[12:01:08] [DEBUG] Caching ingested rate limit data for: d28a133af187e91d71d96a223467ce49
[12:01:08] [DEBUG] GET /oauth2/applications/@me Has exhausted its ratelimit (1000)! Locking route for 0.001 seconds
[12:01:08] [DEBUG] GET /oauth2/applications/@me Received 200 :: [0/1000 calls remaining]
[12:01:08] [WARNING] Setting sync_ext to True by default for syncing changes
[12:01:08] [INFO] Loading jurigged
[12:01:08] [DEBUG] Watch D:\Project\Python\qpneruy-Git\music\Main.py
[12:01:08] [DEBUG] Watch D:\Project\Python\qpneruy-Git\music\play.py
[12:01:08] [DEBUG] Watch D:\Project\Python\qpneruy-Git\music\embed.py
[12:01:08] [DEBUG] Watch D:\Project\Python\qpneruy-Git\music\askbard.py
[12:01:08] [DEBUG] Watch D:\Project\Python\qpneruy-Git\music\noi_chu.py
[12:01:08] [DEBUG] Watch D:\Project\Python\qpneruy-Git\music\db_refesh.py
[12:01:08] [DEBUG] Watch D:\Project\Python\qpneruy-Git\music\help.py
[12:01:08] [DEBUG] Caching ingested rate limit data for: 0a6d458104b103c7be293cc9b284d9ee
[12:01:08] [DEBUG] GET /gateway Received 200 :: [99/100 calls remaining]
[12:01:08] [INFO] Shard ID 0 | Starting Shard
[12:01:08] [INFO] Shard ID 0 | Shard is attempting to connect to gateway...
[12:01:08] [DEBUG] Shard ID 0 | Identification payload sent to gateway, requesting intents: 3407613
[12:01:09] [INFO] Shard ID 0 | Gateway connection established
[12:01:09] [DEBUG] Shard ID 0 | Session ID: 652ca9a3a0b0a0f922d3a0f351de5b3d Trace: ['["gateway-prd-us-east1-d-2f71",{"micros":111275,"calls":["id_created",{"micros":1031,"calls":[]},"session_lookup_time",{"micros":3580,"calls":[]},"session_lookup_finished",{"micros":14,"calls":[]},"discord-sessions-prd-2-270",{"micros":106018,"calls":["start_session",{"micros":45334,"calls":["discord-api-dc69f8484-x52xv",{"micros":40421,"calls":["get_user",{"micros":8720},"get_guilds",{"micros":3275},"send_scheduled_deletion_message",{"micros":11},"guild_join_requests",{"micros":945},"authorized_ip_coro",{"micros":12}]}]},"starting_guild_connect",{"micros":66,"calls":[]},"presence_started",{"micros":25368,"calls":[]},"guilds_started",{"micros":175,"calls":[]},"guilds_connect",{"micros":2,"calls":[]},"presence_connect",{"micros":35037,"calls":[]},"connect_finished",{"micros":35044,"calls":[]},"build_ready",{"micros":27,"calls":[]},"clean_ready",{"micros":1,"calls":[]},"optimize_ready",{"micros":1,"calls":[]},"split_ready",{"micros":1,"calls":[]}]}]}]']
[12:01:09] [DEBUG] Dispatching Event: websocket_ready
[12:01:09] [DEBUG] Dispatching Event: guild_join
[12:01:09] [DEBUG] Dispatching Event: guild_join
[12:01:09] [DEBUG] Dispatching Event: guild_join
[12:01:09] [DEBUG] Dispatching Event: guild_join
[12:01:09] [DEBUG] Dispatching Event: guild_join
[12:01:09] [DEBUG] Dispatching Event: voice_user_leave
[12:01:09] [DEBUG] Shard ID 0 | No processor for `raw_channel_topic_update`
[12:01:09] [DEBUG] Shard ID 0 | No processor for `raw_voice_channel_status_update`
[12:01:09] [DEBUG] Caching ingested rate limit data for: dd84d9818020c27975c0d5ab4a794d44
[12:01:09] [DEBUG] GET /applications/{application_id}/commands Has exhausted its ratelimit (1000)! Locking route for 0.001 seconds
[12:01:09] [DEBUG] GET /applications/{application_id}/commands Received 200 :: [0/1000 calls remaining]
[12:01:09] [DEBUG] Waiting for bucket dd84d9818020c27975c0d5ab4a794d44 to unlock.
[12:01:09] [DEBUG] Caching ingested rate limit data for: dd84d9818020c27975c0d5ab4a794d44
[12:01:09] [DEBUG] GET /applications/{application_id}/commands Has exhausted its ratelimit (1000)! Locking route for 0.001 seconds
[12:01:09] [DEBUG] GET /applications/{application_id}/commands Received 200 :: [0/1000 calls remaining]
[12:01:10] [DEBUG] 0 is already up-to-date with 15 commands.
[12:01:10] [DEBUG] Sync of 1 scopes took 0.780194200007827 seconds
[12:01:10] [DEBUG] Dispatching Event: startup
[12:01:10] [DEBUG] Sending data to websocket: {"op": 3, "d": {"since": 1702962070002, "activities": [{"name": "/help for helpful", "type": 0}], "status": "idle", "afk": false}}
[12:01:10] [DEBUG] Caching ingested rate limit data for: fa219a28141de0d32b282911f0453428
[12:01:10] [DEBUG] DELETE /channels/1186533487394697286 Has exhausted its ratelimit (1000)! Locking route for 0.001 seconds
[12:01:10] [DEBUG] DELETE /channels/1186533487394697286 Received 200 :: [0/1000 calls remaining]
[12:01:17] [DEBUG] Dispatching Event: voice_user_join
[12:01:18] [DEBUG] Caching ingested rate limit data for: be56019ae011689ff5baf218062aacf5
[12:01:18] [DEBUG] POST /guilds/1067024293709496340/channels Received 201 :: [1996/2000 calls remaining]
[12:01:18] [DEBUG] Caching ingested rate limit data for: 6e836da6cef38ba2f3dfd8568a4e9631
[12:01:18] [DEBUG] PATCH /channels/1186533697143443488 Received 200 :: [9/10 calls remaining]
[12:01:19] [DEBUG] Shard ID 0 | No processor for `raw_channel_topic_update`
[12:01:19] [DEBUG] Shard ID 0 | No processor for `raw_voice_channel_status_update`
[12:01:19] [DEBUG] Caching ingested rate limit data for: c7f060a5d9790cb6f53000110a7b7edf
[12:01:19] [DEBUG] PATCH /guilds/1067024293709496340/members/{user_id} Received 200 :: [9/10 calls remaining]
[12:01:23] [DEBUG] Sending heartbeat every 41.25 seconds
[12:01:23] [DEBUG] Sending data to websocket: {"op": 1, "d": 20}
[12:01:23] [DEBUG] Shard ID 0 | ❤ Gateway is sending a Heartbeat
[12:01:23] [DEBUG] Shard ID 0 | ❤ Received heartbeat acknowledgement from gateway
[12:01:25] [ERROR] Jurigged encountered an error
Traceback (most recent call last):
  File "C:\Users\huuti\AppData\Local\Programs\Python\Python311\Lib\site-packages\jurigged\codetools.py", line 493, in _process_child_correspondence
    orig.apply_correspondence(
  File "C:\Users\huuti\AppData\Local\Programs\Python\Python311\Lib\site-packages\jurigged\codetools.py", line 704, in apply_correspondence
    new_obj = self.reevaluate(corr.new.node, glb)
              ^^^^^^^^^^^^^^^^^^^^^^^^^^^^^^^^^^^
  File "C:\Users\huuti\AppData\Local\Programs\Python\Python311\Lib\site-packages\jurigged\codetools.py", line 801, in reevaluate
    conform(self.get_object(), new_obj)
  File "C:\Users\huuti\AppData\Local\Programs\Python\Python311\Lib\site-packages\codefind\registry.py", line 118, in conform
    self.conform(obj1, obj2.__code__)
  File "C:\Users\huuti\AppData\Local\Programs\Python\Python311\Lib\site-packages\codefind\registry.py", line 123, in conform
    fv1 = obj1.__code__.co_freevars
          ^^^^^^^^^^^^^
AttributeError: 'NoneType' object has no attribute '__code__'
[12:01:25] [ERROR] Jurigged encountered an error
Traceback (most recent call last):
  File "C:\Users\huuti\AppData\Local\Programs\Python\Python311\Lib\site-packages\jurigged\codetools.py", line 493, in _process_child_correspondence
    orig.apply_correspondence(
  File "C:\Users\huuti\AppData\Local\Programs\Python\Python311\Lib\site-packages\jurigged\codetools.py", line 704, in apply_correspondence
    new_obj = self.reevaluate(corr.new.node, glb)
              ^^^^^^^^^^^^^^^^^^^^^^^^^^^^^^^^^^^
  File "C:\Users\huuti\AppData\Local\Programs\Python\Python311\Lib\site-packages\jurigged\codetools.py", line 801, in reevaluate
    conform(self.get_object(), new_obj)
  File "C:\Users\huuti\AppData\Local\Programs\Python\Python311\Lib\site-packages\codefind\registry.py", line 118, in conform
    self.conform(obj1, obj2.__code__)
  File "C:\Users\huuti\AppData\Local\Programs\Python\Python311\Lib\site-packages\codefind\registry.py", line 123, in conform
    fv1 = obj1.__code__.co_freevars
          ^^^^^^^^^^^^^
AttributeError: 'NoneType' object has no attribute '__code__'
[12:01:25] [DEBUG] Update __main__:1
[12:01:25] [DEBUG] Update __main__:1
[12:01:31] [DEBUG] Dispatching Event: voice_user_leave
[12:01:31] [DEBUG] Shard ID 0 | No processor for `raw_channel_topic_update`
[12:01:31] [DEBUG] Shard ID 0 | No processor for `raw_voice_channel_status_update`
[12:01:32] [DEBUG] Caching ingested rate limit data for: fa219a28141de0d32b282911f0453428
[12:01:32] [DEBUG] DELETE /channels/1186533697143443488 Has exhausted its ratelimit (1000)! Locking route for 0.001 seconds
[12:01:32] [DEBUG] DELETE /channels/1186533697143443488 Received 200 :: [0/1000 calls remaining]
[12:01:33] [DEBUG] Dispatching Event: voice_user_join
[12:01:33] [DEBUG] Caching ingested rate limit data for: be56019ae011689ff5baf218062aacf5
[12:01:33] [DEBUG] POST /guilds/1067024293709496340/channels Received 201 :: [1995/2000 calls remaining]
[12:01:34] [DEBUG] Caching ingested rate limit data for: 6e836da6cef38ba2f3dfd8568a4e9631
[12:01:34] [DEBUG] PATCH /channels/1186533760733298830 Received 200 :: [9/10 calls remaining]
[12:01:34] [DEBUG] Shard ID 0 | No processor for `raw_channel_topic_update`
[12:01:34] [DEBUG] Shard ID 0 | No processor for `raw_voice_channel_status_update`
[12:01:34] [DEBUG] Caching ingested rate limit data for: c7f060a5d9790cb6f53000110a7b7edf
[12:01:34] [DEBUG] PATCH /guilds/1067024293709496340/members/{user_id} Received 200 :: [9/10 calls remaining]
[12:02:04] [DEBUG] Sending data to websocket: {"op": 1, "d": 34}
[12:02:04] [DEBUG] Shard ID 0 | ❤ Gateway is sending a Heartbeat
[12:02:04] [DEBUG] Shard ID 0 | ❤ Received heartbeat acknowledgement from gateway
[12:02:09] [ERROR] Jurigged encountered an error
Traceback (most recent call last):
  File "C:\Users\huuti\AppData\Local\Programs\Python\Python311\Lib\site-packages\jurigged\codetools.py", line 493, in _process_child_correspondence
    orig.apply_correspondence(
  File "C:\Users\huuti\AppData\Local\Programs\Python\Python311\Lib\site-packages\jurigged\codetools.py", line 704, in apply_correspondence
    new_obj = self.reevaluate(corr.new.node, glb)
              ^^^^^^^^^^^^^^^^^^^^^^^^^^^^^^^^^^^
  File "C:\Users\huuti\AppData\Local\Programs\Python\Python311\Lib\site-packages\jurigged\codetools.py", line 801, in reevaluate
    conform(self.get_object(), new_obj)
  File "C:\Users\huuti\AppData\Local\Programs\Python\Python311\Lib\site-packages\codefind\registry.py", line 118, in conform
    self.conform(obj1, obj2.__code__)
  File "C:\Users\huuti\AppData\Local\Programs\Python\Python311\Lib\site-packages\codefind\registry.py", line 123, in conform
    fv1 = obj1.__code__.co_freevars
          ^^^^^^^^^^^^^
AttributeError: 'NoneType' object has no attribute '__code__'
[12:02:09] [ERROR] Jurigged encountered an error
Traceback (most recent call last):
  File "C:\Users\huuti\AppData\Local\Programs\Python\Python311\Lib\site-packages\jurigged\codetools.py", line 493, in _process_child_correspondence
    orig.apply_correspondence(
  File "C:\Users\huuti\AppData\Local\Programs\Python\Python311\Lib\site-packages\jurigged\codetools.py", line 704, in apply_correspondence
    new_obj = self.reevaluate(corr.new.node, glb)
              ^^^^^^^^^^^^^^^^^^^^^^^^^^^^^^^^^^^
  File "C:\Users\huuti\AppData\Local\Programs\Python\Python311\Lib\site-packages\jurigged\codetools.py", line 801, in reevaluate
    conform(self.get_object(), new_obj)
  File "C:\Users\huuti\AppData\Local\Programs\Python\Python311\Lib\site-packages\codefind\registry.py", line 118, in conform
    self.conform(obj1, obj2.__code__)
  File "C:\Users\huuti\AppData\Local\Programs\Python\Python311\Lib\site-packages\codefind\registry.py", line 123, in conform
    fv1 = obj1.__code__.co_freevars
          ^^^^^^^^^^^^^
AttributeError: 'NoneType' object has no attribute '__code__'
[12:02:09] [ERROR] Jurigged encountered an error
Traceback (most recent call last):
  File "C:\Users\huuti\AppData\Local\Programs\Python\Python311\Lib\site-packages\jurigged\codetools.py", line 493, in _process_child_correspondence
    orig.apply_correspondence(
  File "C:\Users\huuti\AppData\Local\Programs\Python\Python311\Lib\site-packages\jurigged\codetools.py", line 704, in apply_correspondence
    new_obj = self.reevaluate(corr.new.node, glb)
              ^^^^^^^^^^^^^^^^^^^^^^^^^^^^^^^^^^^
  File "C:\Users\huuti\AppData\Local\Programs\Python\Python311\Lib\site-packages\jurigged\codetools.py", line 801, in reevaluate
    conform(self.get_object(), new_obj)
  File "C:\Users\huuti\AppData\Local\Programs\Python\Python311\Lib\site-packages\codefind\registry.py", line 118, in conform
    self.conform(obj1, obj2.__code__)
  File "C:\Users\huuti\AppData\Local\Programs\Python\Python311\Lib\site-packages\codefind\registry.py", line 123, in conform
    fv1 = obj1.__code__.co_freevars
          ^^^^^^^^^^^^^
AttributeError: 'NoneType' object has no attribute '__code__'
[12:02:09] [DEBUG] Update __main__:1
[12:02:09] [ERROR] Jurigged encountered an error
Traceback (most recent call last):
  File "C:\Users\huuti\AppData\Local\Programs\Python\Python311\Lib\site-packages\jurigged\codetools.py", line 493, in _process_child_correspondence
    orig.apply_correspondence(
  File "C:\Users\huuti\AppData\Local\Programs\Python\Python311\Lib\site-packages\jurigged\codetools.py", line 704, in apply_correspondence
    new_obj = self.reevaluate(corr.new.node, glb)
              ^^^^^^^^^^^^^^^^^^^^^^^^^^^^^^^^^^^
  File "C:\Users\huuti\AppData\Local\Programs\Python\Python311\Lib\site-packages\jurigged\codetools.py", line 801, in reevaluate
    conform(self.get_object(), new_obj)
  File "C:\Users\huuti\AppData\Local\Programs\Python\Python311\Lib\site-packages\codefind\registry.py", line 118, in conform
    self.conform(obj1, obj2.__code__)
  File "C:\Users\huuti\AppData\Local\Programs\Python\Python311\Lib\site-packages\codefind\registry.py", line 123, in conform
    fv1 = obj1.__code__.co_freevars
          ^^^^^^^^^^^^^
AttributeError: 'NoneType' object has no attribute '__code__'
[12:02:09] [DEBUG] Add __main__.__leave:121
[12:02:09] [DEBUG] Add __main__._setup:140
[12:02:09] [ERROR] Jurigged encountered an error
Traceback (most recent call last):
  File "C:\Users\huuti\AppData\Local\Programs\Python\Python311\Lib\site-packages\jurigged\codetools.py", line 480, in _process_child_correspondence
    self.evaluate_child(new)
  File "C:\Users\huuti\AppData\Local\Programs\Python\Python311\Lib\site-packages\jurigged\codetools.py", line 625, in evaluate_child
    return child.evaluate(self.get_globals(), None)
           ^^^^^^^^^^^^^^^^^^^^^^^^^^^^^^^^^^^^^^^^
  File "C:\Users\huuti\AppData\Local\Programs\Python\Python311\Lib\site-packages\jurigged\codetools.py", line 245, in evaluate
    exec(code, glb, lcl)
  File "D:\Project\Python\qpneruy-Git\music\Main.py", line 154, in <adjust>
    bot.load_extension("play")
  File "C:\Users\huuti\AppData\Local\Programs\Python\Python311\Lib\site-packages\interactions\client\client.py", line 2003, in load_extension
    raise Exception(f"{module_name} already loaded")
Exception: play already loaded
[12:02:09] [ERROR] Jurigged encountered an error
Traceback (most recent call last):
  File "C:\Users\huuti\AppData\Local\Programs\Python\Python311\Lib\site-packages\jurigged\codetools.py", line 480, in _process_child_correspondence
    self.evaluate_child(new)
  File "C:\Users\huuti\AppData\Local\Programs\Python\Python311\Lib\site-packages\jurigged\codetools.py", line 625, in evaluate_child
    return child.evaluate(self.get_globals(), None)
           ^^^^^^^^^^^^^^^^^^^^^^^^^^^^^^^^^^^^^^^^
  File "C:\Users\huuti\AppData\Local\Programs\Python\Python311\Lib\site-packages\jurigged\codetools.py", line 245, in evaluate
    exec(code, glb, lcl)
  File "D:\Project\Python\qpneruy-Git\music\Main.py", line 155, in <adjust>
    bot.load_extension("askbard")
  File "C:\Users\huuti\AppData\Local\Programs\Python\Python311\Lib\site-packages\interactions\client\client.py", line 2003, in load_extension
    raise Exception(f"{module_name} already loaded")
Exception: askbard already loaded
[12:02:09] [ERROR] Jurigged encountered an error
Traceback (most recent call last):
  File "C:\Users\huuti\AppData\Local\Programs\Python\Python311\Lib\site-packages\jurigged\codetools.py", line 480, in _process_child_correspondence
    self.evaluate_child(new)
  File "C:\Users\huuti\AppData\Local\Programs\Python\Python311\Lib\site-packages\jurigged\codetools.py", line 625, in evaluate_child
    return child.evaluate(self.get_globals(), None)
           ^^^^^^^^^^^^^^^^^^^^^^^^^^^^^^^^^^^^^^^^
  File "C:\Users\huuti\AppData\Local\Programs\Python\Python311\Lib\site-packages\jurigged\codetools.py", line 245, in evaluate
    exec(code, glb, lcl)
  File "D:\Project\Python\qpneruy-Git\music\Main.py", line 156, in <adjust>
    bot.load_extension("noi_chu")
  File "C:\Users\huuti\AppData\Local\Programs\Python\Python311\Lib\site-packages\interactions\client\client.py", line 2003, in load_extension
    raise Exception(f"{module_name} already loaded")
Exception: noi_chu already loaded
[12:02:09] [ERROR] Jurigged encountered an error
Traceback (most recent call last):
  File "C:\Users\huuti\AppData\Local\Programs\Python\Python311\Lib\site-packages\jurigged\codetools.py", line 480, in _process_child_correspondence
    self.evaluate_child(new)
  File "C:\Users\huuti\AppData\Local\Programs\Python\Python311\Lib\site-packages\jurigged\codetools.py", line 625, in evaluate_child
    return child.evaluate(self.get_globals(), None)
           ^^^^^^^^^^^^^^^^^^^^^^^^^^^^^^^^^^^^^^^^
  File "C:\Users\huuti\AppData\Local\Programs\Python\Python311\Lib\site-packages\jurigged\codetools.py", line 245, in evaluate
    exec(code, glb, lcl)
  File "D:\Project\Python\qpneruy-Git\music\Main.py", line 157, in <adjust>
    bot.load_extension("db_refesh")
  File "C:\Users\huuti\AppData\Local\Programs\Python\Python311\Lib\site-packages\interactions\client\client.py", line 2003, in load_extension
    raise Exception(f"{module_name} already loaded")
Exception: db_refesh already loaded
[12:02:09] [ERROR] Jurigged encountered an error
Traceback (most recent call last):
  File "C:\Users\huuti\AppData\Local\Programs\Python\Python311\Lib\site-packages\jurigged\codetools.py", line 480, in _process_child_correspondence
    self.evaluate_child(new)
  File "C:\Users\huuti\AppData\Local\Programs\Python\Python311\Lib\site-packages\jurigged\codetools.py", line 625, in evaluate_child
    return child.evaluate(self.get_globals(), None)
           ^^^^^^^^^^^^^^^^^^^^^^^^^^^^^^^^^^^^^^^^
  File "C:\Users\huuti\AppData\Local\Programs\Python\Python311\Lib\site-packages\jurigged\codetools.py", line 245, in evaluate
    exec(code, glb, lcl)
  File "D:\Project\Python\qpneruy-Git\music\Main.py", line 158, in <adjust>
    bot.load_extension("help")
  File "C:\Users\huuti\AppData\Local\Programs\Python\Python311\Lib\site-packages\interactions\client\client.py", line 2003, in load_extension
    raise Exception(f"{module_name} already loaded")
Exception: help already loaded
[12:02:09] [DEBUG] Added callback: __leave
[12:02:09] [ERROR] Jurigged encountered an error
Traceback (most recent call last):
  File "C:\Users\huuti\AppData\Local\Programs\Python\Python311\Lib\site-packages\jurigged\codetools.py", line 480, in _process_child_correspondence
    self.evaluate_child(new)
  File "C:\Users\huuti\AppData\Local\Programs\Python\Python311\Lib\site-packages\jurigged\codetools.py", line 625, in evaluate_child
    return child.evaluate(self.get_globals(), None)
           ^^^^^^^^^^^^^^^^^^^^^^^^^^^^^^^^^^^^^^^^
  File "C:\Users\huuti\AppData\Local\Programs\Python\Python311\Lib\site-packages\jurigged\codetools.py", line 245, in evaluate
    exec(code, glb, lcl)
  File "D:\Project\Python\qpneruy-Git\music\Main.py", line 160, in <adjust>
    bot.start(Token)
  File "C:\Users\huuti\AppData\Local\Programs\Python\Python311\Lib\site-packages\interactions\client\client.py", line 993, in start
    asyncio.run(self.astart(token))
  File "C:\Users\huuti\AppData\Local\Programs\Python\Python311\Lib\asyncio\runners.py", line 190, in run
    return runner.run(main)
           ^^^^^^^^^^^^^^^^
  File "C:\Users\huuti\AppData\Local\Programs\Python\Python311\Lib\asyncio\runners.py", line 118, in run
    return self._loop.run_until_complete(task)
           ^^^^^^^^^^^^^^^^^^^^^^^^^^^^^^^^^^^
  File "C:\Users\huuti\AppData\Local\Programs\Python\Python311\Lib\asyncio\base_events.py", line 653, in run_until_complete
    return future.result()
           ^^^^^^^^^^^^^^^
  File "C:\Users\huuti\AppData\Local\Programs\Python\Python311\Lib\site-packages\interactions\client\client.py", line 949, in astart
    await self.login(token)
  File "C:\Users\huuti\AppData\Local\Programs\Python\Python311\Lib\site-packages\interactions\client\client.py", line 923, in login
    self._gather_callbacks()
  File "C:\Users\huuti\AppData\Local\Programs\Python\Python311\Lib\site-packages\interactions\client\client.py", line 1420, in _gather_callbacks
    process(main_commands, "__main__")
  File "C:\Users\huuti\AppData\Local\Programs\Python\Python311\Lib\site-packages\interactions\client\client.py", line 1406, in process
    self.add_command(func)
  File "C:\Users\huuti\AppData\Local\Programs\Python\Python311\Lib\site-packages\interactions\client\client.py", line 1379, in add_command
    self.add_interaction(func)
  File "C:\Users\huuti\AppData\Local\Programs\Python\Python311\Lib\site-packages\interactions\client\client.py", line 1294, in add_interaction
    raise ValueError(f"Duplicate Command! {scope}::{old_cmd.resolved_name}")
ValueError: Duplicate Command! 0::about
[12:02:09] [DEBUG] Update __main__:1
[12:02:26] [ERROR] Jurigged encountered an error
Traceback (most recent call last):
  File "C:\Users\huuti\AppData\Local\Programs\Python\Python311\Lib\site-packages\jurigged\codetools.py", line 493, in _process_child_correspondence
    orig.apply_correspondence(
  File "C:\Users\huuti\AppData\Local\Programs\Python\Python311\Lib\site-packages\jurigged\codetools.py", line 704, in apply_correspondence
    new_obj = self.reevaluate(corr.new.node, glb)
              ^^^^^^^^^^^^^^^^^^^^^^^^^^^^^^^^^^^
  File "C:\Users\huuti\AppData\Local\Programs\Python\Python311\Lib\site-packages\jurigged\codetools.py", line 801, in reevaluate
    conform(self.get_object(), new_obj)
  File "C:\Users\huuti\AppData\Local\Programs\Python\Python311\Lib\site-packages\codefind\registry.py", line 118, in conform
    self.conform(obj1, obj2.__code__)
  File "C:\Users\huuti\AppData\Local\Programs\Python\Python311\Lib\site-packages\codefind\registry.py", line 123, in conform
    fv1 = obj1.__code__.co_freevars
          ^^^^^^^^^^^^^
AttributeError: 'NoneType' object has no attribute '__code__'
[12:02:26] [ERROR] Jurigged encountered an error
Traceback (most recent call last):
  File "C:\Users\huuti\AppData\Local\Programs\Python\Python311\Lib\site-packages\jurigged\codetools.py", line 493, in _process_child_correspondence
    orig.apply_correspondence(
  File "C:\Users\huuti\AppData\Local\Programs\Python\Python311\Lib\site-packages\jurigged\codetools.py", line 704, in apply_correspondence
    new_obj = self.reevaluate(corr.new.node, glb)
              ^^^^^^^^^^^^^^^^^^^^^^^^^^^^^^^^^^^
  File "C:\Users\huuti\AppData\Local\Programs\Python\Python311\Lib\site-packages\jurigged\codetools.py", line 801, in reevaluate
    conform(self.get_object(), new_obj)
  File "C:\Users\huuti\AppData\Local\Programs\Python\Python311\Lib\site-packages\codefind\registry.py", line 118, in conform
    self.conform(obj1, obj2.__code__)
  File "C:\Users\huuti\AppData\Local\Programs\Python\Python311\Lib\site-packages\codefind\registry.py", line 123, in conform
    fv1 = obj1.__code__.co_freevars
          ^^^^^^^^^^^^^
AttributeError: 'NoneType' object has no attribute '__code__'
[12:02:26] [DEBUG] Delete __main__.__leave:165
[12:02:26] [DEBUG] Add __main__.__leave:121
[12:02:26] [DEBUG] Delete __main__._setup:184
[12:02:26] [DEBUG] Add __main__._setup:140
[12:02:26] [DEBUG] Delete __main__:198 | bot.load_extension("play")
[12:02:26] [ERROR] Jurigged encountered an error
Traceback (most recent call last):
  File "C:\Users\huuti\AppData\Local\Programs\Python\Python311\Lib\site-packages\jurigged\codetools.py", line 480, in _process_child_correspondence
    self.evaluate_child(new)
  File "C:\Users\huuti\AppData\Local\Programs\Python\Python311\Lib\site-packages\jurigged\codetools.py", line 625, in evaluate_child
    return child.evaluate(self.get_globals(), None)
           ^^^^^^^^^^^^^^^^^^^^^^^^^^^^^^^^^^^^^^^^
  File "C:\Users\huuti\AppData\Local\Programs\Python\Python311\Lib\site-packages\jurigged\codetools.py", line 245, in evaluate
    exec(code, glb, lcl)
  File "D:\Project\Python\qpneruy-Git\music\Main.py", line 154, in <adjust>
    bot.load_extension("play")
  File "C:\Users\huuti\AppData\Local\Programs\Python\Python311\Lib\site-packages\interactions\client\client.py", line 2003, in load_extension
    raise Exception(f"{module_name} already loaded")
Exception: play already loaded
[12:02:26] [DEBUG] Delete __main__:199 | bot.load_extension("askbard")
[12:02:26] [ERROR] Jurigged encountered an error
Traceback (most recent call last):
  File "C:\Users\huuti\AppData\Local\Programs\Python\Python311\Lib\site-packages\jurigged\codetools.py", line 480, in _process_child_correspondence
    self.evaluate_child(new)
  File "C:\Users\huuti\AppData\Local\Programs\Python\Python311\Lib\site-packages\jurigged\codetools.py", line 625, in evaluate_child
    return child.evaluate(self.get_globals(), None)
           ^^^^^^^^^^^^^^^^^^^^^^^^^^^^^^^^^^^^^^^^
  File "C:\Users\huuti\AppData\Local\Programs\Python\Python311\Lib\site-packages\jurigged\codetools.py", line 245, in evaluate
    exec(code, glb, lcl)
  File "D:\Project\Python\qpneruy-Git\music\Main.py", line 155, in <adjust>
    bot.load_extension("askbard")
  File "C:\Users\huuti\AppData\Local\Programs\Python\Python311\Lib\site-packages\interactions\client\client.py", line 2003, in load_extension
    raise Exception(f"{module_name} already loaded")
Exception: askbard already loaded
[12:02:26] [DEBUG] Delete __main__:200 | bot.load_extension("noi_chu")
[12:02:26] [ERROR] Jurigged encountered an error
Traceback (most recent call last):
  File "C:\Users\huuti\AppData\Local\Programs\Python\Python311\Lib\site-packages\jurigged\codetools.py", line 480, in _process_child_correspondence
    self.evaluate_child(new)
  File "C:\Users\huuti\AppData\Local\Programs\Python\Python311\Lib\site-packages\jurigged\codetools.py", line 625, in evaluate_child
    return child.evaluate(self.get_globals(), None)
           ^^^^^^^^^^^^^^^^^^^^^^^^^^^^^^^^^^^^^^^^
  File "C:\Users\huuti\AppData\Local\Programs\Python\Python311\Lib\site-packages\jurigged\codetools.py", line 245, in evaluate
    exec(code, glb, lcl)
  File "D:\Project\Python\qpneruy-Git\music\Main.py", line 156, in <adjust>
    bot.load_extension("noi_chu")
  File "C:\Users\huuti\AppData\Local\Programs\Python\Python311\Lib\site-packages\interactions\client\client.py", line 2003, in load_extension
    raise Exception(f"{module_name} already loaded")
Exception: noi_chu already loaded
[12:02:26] [DEBUG] Delete __main__:201 | bot.load_extension("db_refesh")
[12:02:26] [ERROR] Jurigged encountered an error
Traceback (most recent call last):
  File "C:\Users\huuti\AppData\Local\Programs\Python\Python311\Lib\site-packages\jurigged\codetools.py", line 480, in _process_child_correspondence
    self.evaluate_child(new)
  File "C:\Users\huuti\AppData\Local\Programs\Python\Python311\Lib\site-packages\jurigged\codetools.py", line 625, in evaluate_child
    return child.evaluate(self.get_globals(), None)
           ^^^^^^^^^^^^^^^^^^^^^^^^^^^^^^^^^^^^^^^^
  File "C:\Users\huuti\AppData\Local\Programs\Python\Python311\Lib\site-packages\jurigged\codetools.py", line 245, in evaluate
    exec(code, glb, lcl)
  File "D:\Project\Python\qpneruy-Git\music\Main.py", line 157, in <adjust>
    bot.load_extension("db_refesh")
  File "C:\Users\huuti\AppData\Local\Programs\Python\Python311\Lib\site-packages\interactions\client\client.py", line 2003, in load_extension
    raise Exception(f"{module_name} already loaded")
Exception: db_refesh already loaded
[12:02:26] [DEBUG] Delete __main__:202 | bot.load_extension("help")
[12:02:26] [ERROR] Jurigged encountered an error
Traceback (most recent call last):
  File "C:\Users\huuti\AppData\Local\Programs\Python\Python311\Lib\site-packages\jurigged\codetools.py", line 480, in _process_child_correspondence
    self.evaluate_child(new)
  File "C:\Users\huuti\AppData\Local\Programs\Python\Python311\Lib\site-packages\jurigged\codetools.py", line 625, in evaluate_child
    return child.evaluate(self.get_globals(), None)
           ^^^^^^^^^^^^^^^^^^^^^^^^^^^^^^^^^^^^^^^^
  File "C:\Users\huuti\AppData\Local\Programs\Python\Python311\Lib\site-packages\jurigged\codetools.py", line 245, in evaluate
    exec(code, glb, lcl)
  File "D:\Project\Python\qpneruy-Git\music\Main.py", line 158, in <adjust>
    bot.load_extension("help")
  File "C:\Users\huuti\AppData\Local\Programs\Python\Python311\Lib\site-packages\interactions\client\client.py", line 2003, in load_extension
    raise Exception(f"{module_name} already loaded")
Exception: help already loaded
[12:02:26] [DEBUG] Delete __main__:204 | bot.start(Token)
[12:02:26] [DEBUG] Update __main__:1
[12:02:26] [DEBUG] Added callback: __leave
[12:02:26] [ERROR] Jurigged encountered an error
Traceback (most recent call last):
  File "C:\Users\huuti\AppData\Local\Programs\Python\Python311\Lib\site-packages\jurigged\codetools.py", line 480, in _process_child_correspondence
    self.evaluate_child(new)
  File "C:\Users\huuti\AppData\Local\Programs\Python\Python311\Lib\site-packages\jurigged\codetools.py", line 625, in evaluate_child
    return child.evaluate(self.get_globals(), None)
           ^^^^^^^^^^^^^^^^^^^^^^^^^^^^^^^^^^^^^^^^
  File "C:\Users\huuti\AppData\Local\Programs\Python\Python311\Lib\site-packages\jurigged\codetools.py", line 245, in evaluate
    exec(code, glb, lcl)
  File "D:\Project\Python\qpneruy-Git\music\Main.py", line 160, in <adjust>
    bot.start(Token)
  File "C:\Users\huuti\AppData\Local\Programs\Python\Python311\Lib\site-packages\interactions\client\client.py", line 993, in start
    asyncio.run(self.astart(token))
  File "C:\Users\huuti\AppData\Local\Programs\Python\Python311\Lib\asyncio\runners.py", line 190, in run
    return runner.run(main)
           ^^^^^^^^^^^^^^^^
  File "C:\Users\huuti\AppData\Local\Programs\Python\Python311\Lib\asyncio\runners.py", line 118, in run
    return self._loop.run_until_complete(task)
           ^^^^^^^^^^^^^^^^^^^^^^^^^^^^^^^^^^^
  File "C:\Users\huuti\AppData\Local\Programs\Python\Python311\Lib\asyncio\base_events.py", line 653, in run_until_complete
    return future.result()
           ^^^^^^^^^^^^^^^
  File "C:\Users\huuti\AppData\Local\Programs\Python\Python311\Lib\site-packages\interactions\client\client.py", line 949, in astart
    await self.login(token)
  File "C:\Users\huuti\AppData\Local\Programs\Python\Python311\Lib\site-packages\interactions\client\client.py", line 923, in login
    self._gather_callbacks()
  File "C:\Users\huuti\AppData\Local\Programs\Python\Python311\Lib\site-packages\interactions\client\client.py", line 1420, in _gather_callbacks
    process(main_commands, "__main__")
  File "C:\Users\huuti\AppData\Local\Programs\Python\Python311\Lib\site-packages\interactions\client\client.py", line 1406, in process
    self.add_command(func)
  File "C:\Users\huuti\AppData\Local\Programs\Python\Python311\Lib\site-packages\interactions\client\client.py", line 1379, in add_command
    self.add_interaction(func)
  File "C:\Users\huuti\AppData\Local\Programs\Python\Python311\Lib\site-packages\interactions\client\client.py", line 1294, in add_interaction
    raise ValueError(f"Duplicate Command! {scope}::{old_cmd.resolved_name}")
ValueError: Duplicate Command! 0::about
[12:02:26] [DEBUG] Update __main__:1
[12:02:35] [ERROR] Jurigged encountered an error
Traceback (most recent call last):
  File "C:\Users\huuti\AppData\Local\Programs\Python\Python311\Lib\site-packages\jurigged\codetools.py", line 493, in _process_child_correspondence
    orig.apply_correspondence(
  File "C:\Users\huuti\AppData\Local\Programs\Python\Python311\Lib\site-packages\jurigged\codetools.py", line 704, in apply_correspondence
    new_obj = self.reevaluate(corr.new.node, glb)
              ^^^^^^^^^^^^^^^^^^^^^^^^^^^^^^^^^^^
  File "C:\Users\huuti\AppData\Local\Programs\Python\Python311\Lib\site-packages\jurigged\codetools.py", line 801, in reevaluate
    conform(self.get_object(), new_obj)
  File "C:\Users\huuti\AppData\Local\Programs\Python\Python311\Lib\site-packages\codefind\registry.py", line 118, in conform
    self.conform(obj1, obj2.__code__)
  File "C:\Users\huuti\AppData\Local\Programs\Python\Python311\Lib\site-packages\codefind\registry.py", line 123, in conform
    fv1 = obj1.__code__.co_freevars
          ^^^^^^^^^^^^^
AttributeError: 'NoneType' object has no attribute '__code__'
[12:02:35] [ERROR] Jurigged encountered an error
Traceback (most recent call last):
  File "C:\Users\huuti\AppData\Local\Programs\Python\Python311\Lib\site-packages\jurigged\codetools.py", line 493, in _process_child_correspondence
    orig.apply_correspondence(
  File "C:\Users\huuti\AppData\Local\Programs\Python\Python311\Lib\site-packages\jurigged\codetools.py", line 704, in apply_correspondence
    new_obj = self.reevaluate(corr.new.node, glb)
              ^^^^^^^^^^^^^^^^^^^^^^^^^^^^^^^^^^^
  File "C:\Users\huuti\AppData\Local\Programs\Python\Python311\Lib\site-packages\jurigged\codetools.py", line 801, in reevaluate
    conform(self.get_object(), new_obj)
  File "C:\Users\huuti\AppData\Local\Programs\Python\Python311\Lib\site-packages\codefind\registry.py", line 118, in conform
    self.conform(obj1, obj2.__code__)
  File "C:\Users\huuti\AppData\Local\Programs\Python\Python311\Lib\site-packages\codefind\registry.py", line 123, in conform
    fv1 = obj1.__code__.co_freevars
          ^^^^^^^^^^^^^
AttributeError: 'NoneType' object has no attribute '__code__'
[12:02:35] [ERROR] Jurigged encountered an error
Traceback (most recent call last):
  File "C:\Users\huuti\AppData\Local\Programs\Python\Python311\Lib\site-packages\jurigged\codetools.py", line 493, in _process_child_correspondence
    orig.apply_correspondence(
  File "C:\Users\huuti\AppData\Local\Programs\Python\Python311\Lib\site-packages\jurigged\codetools.py", line 704, in apply_correspondence
    new_obj = self.reevaluate(corr.new.node, glb)
              ^^^^^^^^^^^^^^^^^^^^^^^^^^^^^^^^^^^
  File "C:\Users\huuti\AppData\Local\Programs\Python\Python311\Lib\site-packages\jurigged\codetools.py", line 801, in reevaluate
    conform(self.get_object(), new_obj)
  File "C:\Users\huuti\AppData\Local\Programs\Python\Python311\Lib\site-packages\codefind\registry.py", line 118, in conform
    self.conform(obj1, obj2.__code__)
  File "C:\Users\huuti\AppData\Local\Programs\Python\Python311\Lib\site-packages\codefind\registry.py", line 123, in conform
    fv1 = obj1.__code__.co_freevars
          ^^^^^^^^^^^^^
AttributeError: 'NoneType' object has no attribute '__code__'
[12:02:35] [DEBUG] Add __main__.get_remaining_members:93
[12:02:35] [DEBUG] Delete __main__.__leave:165
[12:02:35] [DEBUG] Add __main__.__join:99
[12:02:35] [DEBUG] Delete __main__._setup:184
[12:02:35] [DEBUG] Add __main__.__leave:121
[12:02:35] [DEBUG] Delete __main__:198 | bot.load_extension("play")
[12:02:35] [DEBUG] Add __main__._setup:140
[12:02:35] [DEBUG] Delete __main__:199 | bot.load_extension("askbard")
[12:02:35] [ERROR] Jurigged encountered an error
Traceback (most recent call last):
  File "C:\Users\huuti\AppData\Local\Programs\Python\Python311\Lib\site-packages\jurigged\codetools.py", line 480, in _process_child_correspondence
    self.evaluate_child(new)
  File "C:\Users\huuti\AppData\Local\Programs\Python\Python311\Lib\site-packages\jurigged\codetools.py", line 625, in evaluate_child
    return child.evaluate(self.get_globals(), None)
           ^^^^^^^^^^^^^^^^^^^^^^^^^^^^^^^^^^^^^^^^
  File "C:\Users\huuti\AppData\Local\Programs\Python\Python311\Lib\site-packages\jurigged\codetools.py", line 245, in evaluate
    exec(code, glb, lcl)
  File "D:\Project\Python\qpneruy-Git\music\Main.py", line 154, in <adjust>
    bot.load_extension("play")
  File "C:\Users\huuti\AppData\Local\Programs\Python\Python311\Lib\site-packages\interactions\client\client.py", line 2003, in load_extension
    raise Exception(f"{module_name} already loaded")
Exception: play already loaded
[12:02:35] [DEBUG] Delete __main__:200 | bot.load_extension("noi_chu")
[12:02:35] [ERROR] Jurigged encountered an error
Traceback (most recent call last):
  File "C:\Users\huuti\AppData\Local\Programs\Python\Python311\Lib\site-packages\jurigged\codetools.py", line 480, in _process_child_correspondence
    self.evaluate_child(new)
  File "C:\Users\huuti\AppData\Local\Programs\Python\Python311\Lib\site-packages\jurigged\codetools.py", line 625, in evaluate_child
    return child.evaluate(self.get_globals(), None)
           ^^^^^^^^^^^^^^^^^^^^^^^^^^^^^^^^^^^^^^^^
  File "C:\Users\huuti\AppData\Local\Programs\Python\Python311\Lib\site-packages\jurigged\codetools.py", line 245, in evaluate
    exec(code, glb, lcl)
  File "D:\Project\Python\qpneruy-Git\music\Main.py", line 155, in <adjust>
    bot.load_extension("askbard")
  File "C:\Users\huuti\AppData\Local\Programs\Python\Python311\Lib\site-packages\interactions\client\client.py", line 2003, in load_extension
    raise Exception(f"{module_name} already loaded")
Exception: askbard already loaded
[12:02:35] [DEBUG] Delete __main__:201 | bot.load_extension("db_refesh")
[12:02:35] [ERROR] Jurigged encountered an error
Traceback (most recent call last):
  File "C:\Users\huuti\AppData\Local\Programs\Python\Python311\Lib\site-packages\jurigged\codetools.py", line 480, in _process_child_correspondence
    self.evaluate_child(new)
  File "C:\Users\huuti\AppData\Local\Programs\Python\Python311\Lib\site-packages\jurigged\codetools.py", line 625, in evaluate_child
    return child.evaluate(self.get_globals(), None)
           ^^^^^^^^^^^^^^^^^^^^^^^^^^^^^^^^^^^^^^^^
  File "C:\Users\huuti\AppData\Local\Programs\Python\Python311\Lib\site-packages\jurigged\codetools.py", line 245, in evaluate
    exec(code, glb, lcl)
  File "D:\Project\Python\qpneruy-Git\music\Main.py", line 156, in <adjust>
    bot.load_extension("noi_chu")
  File "C:\Users\huuti\AppData\Local\Programs\Python\Python311\Lib\site-packages\interactions\client\client.py", line 2003, in load_extension
    raise Exception(f"{module_name} already loaded")
Exception: noi_chu already loaded
[12:02:35] [DEBUG] Delete __main__:202 | bot.load_extension("help")
[12:02:35] [ERROR] Jurigged encountered an error
Traceback (most recent call last):
  File "C:\Users\huuti\AppData\Local\Programs\Python\Python311\Lib\site-packages\jurigged\codetools.py", line 480, in _process_child_correspondence
    self.evaluate_child(new)
  File "C:\Users\huuti\AppData\Local\Programs\Python\Python311\Lib\site-packages\jurigged\codetools.py", line 625, in evaluate_child
    return child.evaluate(self.get_globals(), None)
           ^^^^^^^^^^^^^^^^^^^^^^^^^^^^^^^^^^^^^^^^
  File "C:\Users\huuti\AppData\Local\Programs\Python\Python311\Lib\site-packages\jurigged\codetools.py", line 245, in evaluate
    exec(code, glb, lcl)
  File "D:\Project\Python\qpneruy-Git\music\Main.py", line 157, in <adjust>
    bot.load_extension("db_refesh")
  File "C:\Users\huuti\AppData\Local\Programs\Python\Python311\Lib\site-packages\interactions\client\client.py", line 2003, in load_extension
    raise Exception(f"{module_name} already loaded")
Exception: db_refesh already loaded
[12:02:35] [DEBUG] Delete __main__:204 | bot.start(Token)
[12:02:35] [ERROR] Jurigged encountered an error
Traceback (most recent call last):
  File "C:\Users\huuti\AppData\Local\Programs\Python\Python311\Lib\site-packages\jurigged\codetools.py", line 480, in _process_child_correspondence
    self.evaluate_child(new)
  File "C:\Users\huuti\AppData\Local\Programs\Python\Python311\Lib\site-packages\jurigged\codetools.py", line 625, in evaluate_child
    return child.evaluate(self.get_globals(), None)
           ^^^^^^^^^^^^^^^^^^^^^^^^^^^^^^^^^^^^^^^^
  File "C:\Users\huuti\AppData\Local\Programs\Python\Python311\Lib\site-packages\jurigged\codetools.py", line 245, in evaluate
    exec(code, glb, lcl)
  File "D:\Project\Python\qpneruy-Git\music\Main.py", line 158, in <adjust>
    bot.load_extension("help")
  File "C:\Users\huuti\AppData\Local\Programs\Python\Python311\Lib\site-packages\interactions\client\client.py", line 2003, in load_extension
    raise Exception(f"{module_name} already loaded")
Exception: help already loaded
[12:02:35] [DEBUG] Update __main__:1
[12:02:35] [DEBUG] Added callback: __join
[12:02:35] [DEBUG] Added callback: __leave
[12:02:35] [ERROR] Jurigged encountered an error
Traceback (most recent call last):
  File "C:\Users\huuti\AppData\Local\Programs\Python\Python311\Lib\site-packages\jurigged\codetools.py", line 480, in _process_child_correspondence
    self.evaluate_child(new)
  File "C:\Users\huuti\AppData\Local\Programs\Python\Python311\Lib\site-packages\jurigged\codetools.py", line 625, in evaluate_child
    return child.evaluate(self.get_globals(), None)
           ^^^^^^^^^^^^^^^^^^^^^^^^^^^^^^^^^^^^^^^^
  File "C:\Users\huuti\AppData\Local\Programs\Python\Python311\Lib\site-packages\jurigged\codetools.py", line 245, in evaluate
    exec(code, glb, lcl)
  File "D:\Project\Python\qpneruy-Git\music\Main.py", line 160, in <adjust>
    bot.start(Token)
  File "C:\Users\huuti\AppData\Local\Programs\Python\Python311\Lib\site-packages\interactions\client\client.py", line 993, in start
    asyncio.run(self.astart(token))
  File "C:\Users\huuti\AppData\Local\Programs\Python\Python311\Lib\asyncio\runners.py", line 190, in run
    return runner.run(main)
           ^^^^^^^^^^^^^^^^
  File "C:\Users\huuti\AppData\Local\Programs\Python\Python311\Lib\asyncio\runners.py", line 118, in run
    return self._loop.run_until_complete(task)
           ^^^^^^^^^^^^^^^^^^^^^^^^^^^^^^^^^^^
  File "C:\Users\huuti\AppData\Local\Programs\Python\Python311\Lib\asyncio\base_events.py", line 653, in run_until_complete
    return future.result()
           ^^^^^^^^^^^^^^^
  File "C:\Users\huuti\AppData\Local\Programs\Python\Python311\Lib\site-packages\interactions\client\client.py", line 949, in astart
    await self.login(token)
  File "C:\Users\huuti\AppData\Local\Programs\Python\Python311\Lib\site-packages\interactions\client\client.py", line 923, in login
    self._gather_callbacks()
  File "C:\Users\huuti\AppData\Local\Programs\Python\Python311\Lib\site-packages\interactions\client\client.py", line 1420, in _gather_callbacks
    process(main_commands, "__main__")
  File "C:\Users\huuti\AppData\Local\Programs\Python\Python311\Lib\site-packages\interactions\client\client.py", line 1406, in process
    self.add_command(func)
  File "C:\Users\huuti\AppData\Local\Programs\Python\Python311\Lib\site-packages\interactions\client\client.py", line 1379, in add_command
    self.add_interaction(func)
  File "C:\Users\huuti\AppData\Local\Programs\Python\Python311\Lib\site-packages\interactions\client\client.py", line 1294, in add_interaction
    raise ValueError(f"Duplicate Command! {scope}::{old_cmd.resolved_name}")
ValueError: Duplicate Command! 0::about
[12:02:35] [DEBUG] Update __main__:1
[12:02:41] [ERROR] Jurigged encountered an error
Traceback (most recent call last):
  File "C:\Users\huuti\AppData\Local\Programs\Python\Python311\Lib\site-packages\jurigged\codetools.py", line 493, in _process_child_correspondence
    orig.apply_correspondence(
  File "C:\Users\huuti\AppData\Local\Programs\Python\Python311\Lib\site-packages\jurigged\codetools.py", line 704, in apply_correspondence
    new_obj = self.reevaluate(corr.new.node, glb)
              ^^^^^^^^^^^^^^^^^^^^^^^^^^^^^^^^^^^
  File "C:\Users\huuti\AppData\Local\Programs\Python\Python311\Lib\site-packages\jurigged\codetools.py", line 801, in reevaluate
    conform(self.get_object(), new_obj)
  File "C:\Users\huuti\AppData\Local\Programs\Python\Python311\Lib\site-packages\codefind\registry.py", line 118, in conform
    self.conform(obj1, obj2.__code__)
  File "C:\Users\huuti\AppData\Local\Programs\Python\Python311\Lib\site-packages\codefind\registry.py", line 123, in conform
    fv1 = obj1.__code__.co_freevars
          ^^^^^^^^^^^^^
AttributeError: 'NoneType' object has no attribute '__code__'
[12:02:41] [DEBUG] Delete __main__.__join:99
[12:02:41] [DEBUG] Delete __main__.get_remaining_members:121
[12:02:41] [ERROR] Jurigged encountered an error
Traceback (most recent call last):
  File "C:\Users\huuti\AppData\Local\Programs\Python\Python311\Lib\site-packages\jurigged\codetools.py", line 493, in _process_child_correspondence
    orig.apply_correspondence(
  File "C:\Users\huuti\AppData\Local\Programs\Python\Python311\Lib\site-packages\jurigged\codetools.py", line 704, in apply_correspondence
    new_obj = self.reevaluate(corr.new.node, glb)
              ^^^^^^^^^^^^^^^^^^^^^^^^^^^^^^^^^^^
  File "C:\Users\huuti\AppData\Local\Programs\Python\Python311\Lib\site-packages\jurigged\codetools.py", line 801, in reevaluate
    conform(self.get_object(), new_obj)
  File "C:\Users\huuti\AppData\Local\Programs\Python\Python311\Lib\site-packages\codefind\registry.py", line 118, in conform
    self.conform(obj1, obj2.__code__)
  File "C:\Users\huuti\AppData\Local\Programs\Python\Python311\Lib\site-packages\codefind\registry.py", line 123, in conform
    fv1 = obj1.__code__.co_freevars
          ^^^^^^^^^^^^^
AttributeError: 'NoneType' object has no attribute '__code__'
[12:02:41] [DEBUG] Delete __main__.__leave:193
[12:02:41] [DEBUG] Add __main__.get_remaining_members:92
[12:02:41] [DEBUG] Delete __main__._setup:212
[12:02:41] [DEBUG] Add __main__.__join:98
[12:02:41] [DEBUG] Delete __main__:226 | bot.load_extension("play")
[12:02:41] [DEBUG] Add __main__.__leave:120
[12:02:41] [DEBUG] Delete __main__:227 | bot.load_extension("askbard")
[12:02:41] [DEBUG] Add __main__._setup:139
[12:02:41] [DEBUG] Delete __main__:228 | bot.load_extension("noi_chu")
[12:02:41] [ERROR] Jurigged encountered an error
Traceback (most recent call last):
  File "C:\Users\huuti\AppData\Local\Programs\Python\Python311\Lib\site-packages\jurigged\codetools.py", line 480, in _process_child_correspondence
    self.evaluate_child(new)
  File "C:\Users\huuti\AppData\Local\Programs\Python\Python311\Lib\site-packages\jurigged\codetools.py", line 625, in evaluate_child
    return child.evaluate(self.get_globals(), None)
           ^^^^^^^^^^^^^^^^^^^^^^^^^^^^^^^^^^^^^^^^
  File "C:\Users\huuti\AppData\Local\Programs\Python\Python311\Lib\site-packages\jurigged\codetools.py", line 245, in evaluate
    exec(code, glb, lcl)
  File "D:\Project\Python\qpneruy-Git\music\Main.py", line 153, in <adjust>
    bot.load_extension("play")
  File "C:\Users\huuti\AppData\Local\Programs\Python\Python311\Lib\site-packages\interactions\client\client.py", line 2003, in load_extension
    raise Exception(f"{module_name} already loaded")
Exception: play already loaded
[12:02:41] [DEBUG] Delete __main__:229 | bot.load_extension("db_refesh")
[12:02:41] [ERROR] Jurigged encountered an error
Traceback (most recent call last):
  File "C:\Users\huuti\AppData\Local\Programs\Python\Python311\Lib\site-packages\jurigged\codetools.py", line 480, in _process_child_correspondence
    self.evaluate_child(new)
  File "C:\Users\huuti\AppData\Local\Programs\Python\Python311\Lib\site-packages\jurigged\codetools.py", line 625, in evaluate_child
    return child.evaluate(self.get_globals(), None)
           ^^^^^^^^^^^^^^^^^^^^^^^^^^^^^^^^^^^^^^^^
  File "C:\Users\huuti\AppData\Local\Programs\Python\Python311\Lib\site-packages\jurigged\codetools.py", line 245, in evaluate
    exec(code, glb, lcl)
  File "D:\Project\Python\qpneruy-Git\music\Main.py", line 154, in <adjust>
    bot.load_extension("askbard")
  File "C:\Users\huuti\AppData\Local\Programs\Python\Python311\Lib\site-packages\interactions\client\client.py", line 2003, in load_extension
    raise Exception(f"{module_name} already loaded")
Exception: askbard already loaded
[12:02:41] [DEBUG] Delete __main__:230 | bot.load_extension("help")
[12:02:41] [ERROR] Jurigged encountered an error
Traceback (most recent call last):
  File "C:\Users\huuti\AppData\Local\Programs\Python\Python311\Lib\site-packages\jurigged\codetools.py", line 480, in _process_child_correspondence
    self.evaluate_child(new)
  File "C:\Users\huuti\AppData\Local\Programs\Python\Python311\Lib\site-packages\jurigged\codetools.py", line 625, in evaluate_child
    return child.evaluate(self.get_globals(), None)
           ^^^^^^^^^^^^^^^^^^^^^^^^^^^^^^^^^^^^^^^^
  File "C:\Users\huuti\AppData\Local\Programs\Python\Python311\Lib\site-packages\jurigged\codetools.py", line 245, in evaluate
    exec(code, glb, lcl)
  File "D:\Project\Python\qpneruy-Git\music\Main.py", line 155, in <adjust>
    bot.load_extension("noi_chu")
  File "C:\Users\huuti\AppData\Local\Programs\Python\Python311\Lib\site-packages\interactions\client\client.py", line 2003, in load_extension
    raise Exception(f"{module_name} already loaded")
Exception: noi_chu already loaded
[12:02:41] [DEBUG] Delete __main__:232 | bot.start(Token)
[12:02:41] [ERROR] Jurigged encountered an error
Traceback (most recent call last):
  File "C:\Users\huuti\AppData\Local\Programs\Python\Python311\Lib\site-packages\jurigged\codetools.py", line 480, in _process_child_correspondence
    self.evaluate_child(new)
  File "C:\Users\huuti\AppData\Local\Programs\Python\Python311\Lib\site-packages\jurigged\codetools.py", line 625, in evaluate_child
    return child.evaluate(self.get_globals(), None)
           ^^^^^^^^^^^^^^^^^^^^^^^^^^^^^^^^^^^^^^^^
  File "C:\Users\huuti\AppData\Local\Programs\Python\Python311\Lib\site-packages\jurigged\codetools.py", line 245, in evaluate
    exec(code, glb, lcl)
  File "D:\Project\Python\qpneruy-Git\music\Main.py", line 156, in <adjust>
    bot.load_extension("db_refesh")
  File "C:\Users\huuti\AppData\Local\Programs\Python\Python311\Lib\site-packages\interactions\client\client.py", line 2003, in load_extension
    raise Exception(f"{module_name} already loaded")
Exception: db_refesh already loaded
[12:02:41] [DEBUG] Update __main__:1
[12:02:41] [ERROR] Jurigged encountered an error
Traceback (most recent call last):
  File "C:\Users\huuti\AppData\Local\Programs\Python\Python311\Lib\site-packages\jurigged\codetools.py", line 480, in _process_child_correspondence
    self.evaluate_child(new)
  File "C:\Users\huuti\AppData\Local\Programs\Python\Python311\Lib\site-packages\jurigged\codetools.py", line 625, in evaluate_child
    return child.evaluate(self.get_globals(), None)
           ^^^^^^^^^^^^^^^^^^^^^^^^^^^^^^^^^^^^^^^^
  File "C:\Users\huuti\AppData\Local\Programs\Python\Python311\Lib\site-packages\jurigged\codetools.py", line 245, in evaluate
    exec(code, glb, lcl)
  File "D:\Project\Python\qpneruy-Git\music\Main.py", line 157, in <adjust>
    bot.load_extension("help")
  File "C:\Users\huuti\AppData\Local\Programs\Python\Python311\Lib\site-packages\interactions\client\client.py", line 2003, in load_extension
    raise Exception(f"{module_name} already loaded")
Exception: help already loaded
[12:02:41] [DEBUG] Added callback: __join
[12:02:41] [DEBUG] Added callback: __leave
[12:02:41] [ERROR] Jurigged encountered an error
Traceback (most recent call last):
  File "C:\Users\huuti\AppData\Local\Programs\Python\Python311\Lib\site-packages\jurigged\codetools.py", line 480, in _process_child_correspondence
    self.evaluate_child(new)
  File "C:\Users\huuti\AppData\Local\Programs\Python\Python311\Lib\site-packages\jurigged\codetools.py", line 625, in evaluate_child
    return child.evaluate(self.get_globals(), None)
           ^^^^^^^^^^^^^^^^^^^^^^^^^^^^^^^^^^^^^^^^
  File "C:\Users\huuti\AppData\Local\Programs\Python\Python311\Lib\site-packages\jurigged\codetools.py", line 245, in evaluate
    exec(code, glb, lcl)
  File "D:\Project\Python\qpneruy-Git\music\Main.py", line 159, in <adjust>
    bot.start(Token)
  File "C:\Users\huuti\AppData\Local\Programs\Python\Python311\Lib\site-packages\interactions\client\client.py", line 993, in start
    asyncio.run(self.astart(token))
  File "C:\Users\huuti\AppData\Local\Programs\Python\Python311\Lib\asyncio\runners.py", line 190, in run
    return runner.run(main)
           ^^^^^^^^^^^^^^^^
  File "C:\Users\huuti\AppData\Local\Programs\Python\Python311\Lib\asyncio\runners.py", line 118, in run
    return self._loop.run_until_complete(task)
           ^^^^^^^^^^^^^^^^^^^^^^^^^^^^^^^^^^^
  File "C:\Users\huuti\AppData\Local\Programs\Python\Python311\Lib\asyncio\base_events.py", line 653, in run_until_complete
    return future.result()
           ^^^^^^^^^^^^^^^
  File "C:\Users\huuti\AppData\Local\Programs\Python\Python311\Lib\site-packages\interactions\client\client.py", line 949, in astart
    await self.login(token)
  File "C:\Users\huuti\AppData\Local\Programs\Python\Python311\Lib\site-packages\interactions\client\client.py", line 923, in login
    self._gather_callbacks()
  File "C:\Users\huuti\AppData\Local\Programs\Python\Python311\Lib\site-packages\interactions\client\client.py", line 1420, in _gather_callbacks
    process(main_commands, "__main__")
  File "C:\Users\huuti\AppData\Local\Programs\Python\Python311\Lib\site-packages\interactions\client\client.py", line 1406, in process
    self.add_command(func)
  File "C:\Users\huuti\AppData\Local\Programs\Python\Python311\Lib\site-packages\interactions\client\client.py", line 1379, in add_command
    self.add_interaction(func)
  File "C:\Users\huuti\AppData\Local\Programs\Python\Python311\Lib\site-packages\interactions\client\client.py", line 1294, in add_interaction
    raise ValueError(f"Duplicate Command! {scope}::{old_cmd.resolved_name}")
ValueError: Duplicate Command! 0::about
[12:02:41] [DEBUG] Update __main__:1
[12:02:45] [DEBUG] Sending data to websocket: {"op": 1, "d": 34}
[12:02:45] [DEBUG] Shard ID 0 | ❤ Gateway is sending a Heartbeat
[12:02:45] [DEBUG] Shard ID 0 | ❤ Received heartbeat acknowledgement from gateway
[12:03:24] [DEBUG] Dispatching Event: disconnect
[12:03:24] [DEBUG] Stopping the bot.
[12:03:24] [INFO] Shard ID 0 | Stopping Shard
