[18:14:01] [DEBUG] Running client sanity checks...
[18:14:03] [DEBUG] No setup function found in play
[18:14:03] [DEBUG] Found extension class Music in play: Attempting to load
[18:14:03] [DEBUG] Added callback: Music._menu
[18:14:03] [DEBUG] Added callback: Music._pause
[18:14:03] [DEBUG] Added callback: Music._resume
[18:14:03] [DEBUG] Added callback: Music._skip
[18:14:03] [DEBUG] Added callback: Music._stop
[18:14:03] [DEBUG] Added callback: Music.play
[18:14:03] [DEBUG] Loaded Extension: play
[18:14:03] [DEBUG] No setup function found in askbard
[18:14:03] [DEBUG] Found extension class Bard in askbard: Attempting to load
[18:14:03] [DEBUG] Added callback: Bard._askbard
[18:14:03] [DEBUG] Added callback: Bard._endbard
[18:14:03] [DEBUG] Added callback: Bard.set_bard_channel
[18:14:03] [DEBUG] Loaded Extension: askbard
[18:14:03] [DEBUG] No setup function found in noi_chu
[18:14:03] [DEBUG] Found extension class NoiChu in noi_chu: Attempting to load
[18:14:03] [DEBUG] Added callback: NoiChu._reset
[18:14:03] [DEBUG] Added callback: NoiChu._world_setup
[18:14:03] [DEBUG] Loaded Extension: noi_chu
[18:14:03] [DEBUG] No setup function found in db_refesh
[18:14:03] [DEBUG] Found extension class Database in db_refesh: Attempting to load
[18:14:03] [DEBUG] Loaded Extension: db_refesh
[18:14:03] [DEBUG] Added callback: __join
[18:14:03] [DEBUG] Added callback: __leave
[18:14:03] [DEBUG] Added callback: _about
[18:14:03] [DEBUG] Added callback: _help
[18:14:03] [DEBUG] Added callback: _refresh
[18:14:03] [DEBUG] Added callback: _setup
[18:14:03] [DEBUG] Added callback: _starup
[18:14:03] [DEBUG] 7 callbacks have been loaded from __main__.
[18:14:03] [DEBUG] Added callback: _disconnect
[18:14:03] [DEBUG] Added callback: _on_websocket_ready
[18:14:03] [DEBUG] Added callback: on_autocomplete_completion
[18:14:03] [DEBUG] Added callback: on_autocomplete_error
[18:14:03] [DEBUG] Added callback: on_command_completion
[18:14:03] [DEBUG] Added callback: on_command_error
[18:14:03] [DEBUG] Added callback: on_component_completion
[18:14:03] [DEBUG] Added callback: on_component_error
[18:14:03] [DEBUG] Added callback: on_error
[18:14:03] [DEBUG] Added callback: on_modal_completion
[18:14:03] [DEBUG] Added callback: on_modal_error
[18:14:03] [DEBUG] Added callback: on_resume
[18:14:03] [DEBUG] 12 callbacks have been loaded from Client.
[18:14:03] [DEBUG] Attempting to login
[18:14:04] [DEBUG] Caching ingested rate limit data for: 78bb8553d9352a5a2f89f9def401287a
[18:14:04] [DEBUG] GET /users/@me Has exhausted its ratelimit (1000)! Locking route for 0.001 seconds
[18:14:04] [DEBUG] GET /users/@me Received 200 :: [0/1000 calls remaining]
[18:14:04] [DEBUG] Caching ingested rate limit data for: d28a133af187e91d71d96a223467ce49
[18:14:04] [DEBUG] GET /oauth2/applications/@me Has exhausted its ratelimit (1000)! Locking route for 0.001 seconds
[18:14:04] [DEBUG] GET /oauth2/applications/@me Received 200 :: [0/1000 calls remaining]
[18:14:04] [DEBUG] Caching ingested rate limit data for: 0a6d458104b103c7be293cc9b284d9ee
[18:14:04] [DEBUG] GET /gateway Received 200 :: [99/100 calls remaining]
[18:14:04] [INFO] Shard ID 0 | Starting Shard
[18:14:04] [INFO] Shard ID 0 | Shard is attempting to connect to gateway...
[18:14:04] [DEBUG] Shard ID 0 | Identification payload sent to gateway, requesting intents: 3407613
[18:14:05] [INFO] Shard ID 0 | Gateway connection established
[18:14:05] [DEBUG] Shard ID 0 | Session ID: b34dd245d3449e3493e4164a6529f859 Trace: ['["gateway-prd-us-east1-b-q18v",{"micros":130941,"calls":["id_created",{"micros":2526,"calls":[]},"session_lookup_time",{"micros":380,"calls":[]},"session_lookup_finished",{"micros":17,"calls":[]},"discord-sessions-prd-2-262",{"micros":127659,"calls":["start_session",{"micros":73094,"calls":["discord-api-f65587479-nvrqn",{"micros":66440,"calls":["get_user",{"micros":12163},"get_guilds",{"micros":9432},"send_scheduled_deletion_message",{"micros":13},"guild_join_requests",{"micros":2},"authorized_ip_coro",{"micros":13}]}]},"starting_guild_connect",{"micros":83,"calls":[]},"presence_started",{"micros":247,"calls":[]},"guilds_started",{"micros":208,"calls":[]},"guilds_connect",{"micros":2,"calls":[]},"presence_connect",{"micros":53997,"calls":[]},"connect_finished",{"micros":54003,"calls":[]},"build_ready",{"micros":19,"calls":[]},"clean_ready",{"micros":1,"calls":[]},"optimize_ready",{"micros":1,"calls":[]},"split_ready",{"micros":1,"calls":[]}]}]}]']
[18:14:05] [DEBUG] Dispatching Event: websocket_ready
[18:14:05] [DEBUG] Dispatching Event: guild_join
[18:14:05] [DEBUG] Dispatching Event: error
[18:14:05] [ERROR] Ignoring exception in GuildJoin():
Traceback (most recent call last):
  File "C:\Users\huuti\AppData\Local\Programs\Python\Python311\Lib\site-packages\interactions\client\client.py", line 607, in _async_wrap
    await _coro(_event, *_args, **_kwargs)
  File "C:\Users\huuti\AppData\Local\Programs\Python\Python311\Lib\site-packages\interactions\models\internal\callback.py", line 31, in __call__
    return await self.callback(self._binding, *args, **kwargs)
           ^^^^^^^^^^^^^^^^^^^^^^^^^^^^^^^^^^^^^^^^^^^^^^^^^^^
  File "D:\Project\Python\qpneruy-Git\music\db_refesh.py", line 33, in _on_guild_join
    cursor.execute(query)
  File "C:\Users\huuti\AppData\Local\Programs\Python\Python311\Lib\site-packages\pymysql\cursors.py", line 153, in execute
    result = self._query(query)
             ^^^^^^^^^^^^^^^^^^
  File "C:\Users\huuti\AppData\Local\Programs\Python\Python311\Lib\site-packages\pymysql\cursors.py", line 322, in _query
    conn.query(q)
  File "C:\Users\huuti\AppData\Local\Programs\Python\Python311\Lib\site-packages\pymysql\connections.py", line 558, in query
    self._affected_rows = self._read_query_result(unbuffered=unbuffered)
                          ^^^^^^^^^^^^^^^^^^^^^^^^^^^^^^^^^^^^^^^^^^^^^^
  File "C:\Users\huuti\AppData\Local\Programs\Python\Python311\Lib\site-packages\pymysql\connections.py", line 822, in _read_query_result
    result.read()
  File "C:\Users\huuti\AppData\Local\Programs\Python\Python311\Lib\site-packages\pymysql\connections.py", line 1200, in read
    first_packet = self.connection._read_packet()
                   ^^^^^^^^^^^^^^^^^^^^^^^^^^^^^^
  File "C:\Users\huuti\AppData\Local\Programs\Python\Python311\Lib\site-packages\pymysql\connections.py", line 772, in _read_packet
    packet.raise_for_error()
  File "C:\Users\huuti\AppData\Local\Programs\Python\Python311\Lib\site-packages\pymysql\protocol.py", line 221, in raise_for_error
    err.raise_mysql_exception(self._data)
  File "C:\Users\huuti\AppData\Local\Programs\Python\Python311\Lib\site-packages\pymysql\err.py", line 143, in raise_mysql_exception
    raise errorclass(errno, errval)
pymysql.err.OperationalError: (1050, "Table 'server_1067024293709496340' already exists")

[18:14:05] [DEBUG] Dispatching Event: guild_join
[18:14:05] [DEBUG] Dispatching Event: error
[18:14:05] [ERROR] Ignoring exception in GuildJoin():
Traceback (most recent call last):
  File "C:\Users\huuti\AppData\Local\Programs\Python\Python311\Lib\site-packages\interactions\client\client.py", line 607, in _async_wrap
    await _coro(_event, *_args, **_kwargs)
  File "C:\Users\huuti\AppData\Local\Programs\Python\Python311\Lib\site-packages\interactions\models\internal\callback.py", line 31, in __call__
    return await self.callback(self._binding, *args, **kwargs)
           ^^^^^^^^^^^^^^^^^^^^^^^^^^^^^^^^^^^^^^^^^^^^^^^^^^^
  File "D:\Project\Python\qpneruy-Git\music\db_refesh.py", line 33, in _on_guild_join
    cursor.execute(query)
  File "C:\Users\huuti\AppData\Local\Programs\Python\Python311\Lib\site-packages\pymysql\cursors.py", line 153, in execute
    result = self._query(query)
             ^^^^^^^^^^^^^^^^^^
  File "C:\Users\huuti\AppData\Local\Programs\Python\Python311\Lib\site-packages\pymysql\cursors.py", line 322, in _query
    conn.query(q)
  File "C:\Users\huuti\AppData\Local\Programs\Python\Python311\Lib\site-packages\pymysql\connections.py", line 558, in query
    self._affected_rows = self._read_query_result(unbuffered=unbuffered)
                          ^^^^^^^^^^^^^^^^^^^^^^^^^^^^^^^^^^^^^^^^^^^^^^
  File "C:\Users\huuti\AppData\Local\Programs\Python\Python311\Lib\site-packages\pymysql\connections.py", line 822, in _read_query_result
    result.read()
  File "C:\Users\huuti\AppData\Local\Programs\Python\Python311\Lib\site-packages\pymysql\connections.py", line 1200, in read
    first_packet = self.connection._read_packet()
                   ^^^^^^^^^^^^^^^^^^^^^^^^^^^^^^
  File "C:\Users\huuti\AppData\Local\Programs\Python\Python311\Lib\site-packages\pymysql\connections.py", line 772, in _read_packet
    packet.raise_for_error()
  File "C:\Users\huuti\AppData\Local\Programs\Python\Python311\Lib\site-packages\pymysql\protocol.py", line 221, in raise_for_error
    err.raise_mysql_exception(self._data)
  File "C:\Users\huuti\AppData\Local\Programs\Python\Python311\Lib\site-packages\pymysql\err.py", line 143, in raise_mysql_exception
    raise errorclass(errno, errval)
pymysql.err.OperationalError: (1050, "Table 'server_1159832166998487050' already exists")

[18:14:05] [DEBUG] Dispatching Event: guild_join
[18:14:05] [DEBUG] Dispatching Event: error
[18:14:05] [ERROR] Ignoring exception in GuildJoin():
Traceback (most recent call last):
  File "C:\Users\huuti\AppData\Local\Programs\Python\Python311\Lib\site-packages\interactions\client\client.py", line 607, in _async_wrap
    await _coro(_event, *_args, **_kwargs)
  File "C:\Users\huuti\AppData\Local\Programs\Python\Python311\Lib\site-packages\interactions\models\internal\callback.py", line 31, in __call__
    return await self.callback(self._binding, *args, **kwargs)
           ^^^^^^^^^^^^^^^^^^^^^^^^^^^^^^^^^^^^^^^^^^^^^^^^^^^
  File "D:\Project\Python\qpneruy-Git\music\db_refesh.py", line 33, in _on_guild_join
    cursor.execute(query)
  File "C:\Users\huuti\AppData\Local\Programs\Python\Python311\Lib\site-packages\pymysql\cursors.py", line 153, in execute
    result = self._query(query)
             ^^^^^^^^^^^^^^^^^^
  File "C:\Users\huuti\AppData\Local\Programs\Python\Python311\Lib\site-packages\pymysql\cursors.py", line 322, in _query
    conn.query(q)
  File "C:\Users\huuti\AppData\Local\Programs\Python\Python311\Lib\site-packages\pymysql\connections.py", line 558, in query
    self._affected_rows = self._read_query_result(unbuffered=unbuffered)
                          ^^^^^^^^^^^^^^^^^^^^^^^^^^^^^^^^^^^^^^^^^^^^^^
  File "C:\Users\huuti\AppData\Local\Programs\Python\Python311\Lib\site-packages\pymysql\connections.py", line 822, in _read_query_result
    result.read()
  File "C:\Users\huuti\AppData\Local\Programs\Python\Python311\Lib\site-packages\pymysql\connections.py", line 1200, in read
    first_packet = self.connection._read_packet()
                   ^^^^^^^^^^^^^^^^^^^^^^^^^^^^^^
  File "C:\Users\huuti\AppData\Local\Programs\Python\Python311\Lib\site-packages\pymysql\connections.py", line 772, in _read_packet
    packet.raise_for_error()
  File "C:\Users\huuti\AppData\Local\Programs\Python\Python311\Lib\site-packages\pymysql\protocol.py", line 221, in raise_for_error
    err.raise_mysql_exception(self._data)
  File "C:\Users\huuti\AppData\Local\Programs\Python\Python311\Lib\site-packages\pymysql\err.py", line 143, in raise_mysql_exception
    raise errorclass(errno, errval)
pymysql.err.OperationalError: (1050, "Table 'server_1149195429284692069' already exists")

[18:14:05] [DEBUG] Dispatching Event: guild_join
[18:14:05] [DEBUG] Dispatching Event: error
[18:14:05] [ERROR] Ignoring exception in GuildJoin():
Traceback (most recent call last):
  File "C:\Users\huuti\AppData\Local\Programs\Python\Python311\Lib\site-packages\interactions\client\client.py", line 607, in _async_wrap
    await _coro(_event, *_args, **_kwargs)
  File "C:\Users\huuti\AppData\Local\Programs\Python\Python311\Lib\site-packages\interactions\models\internal\callback.py", line 31, in __call__
    return await self.callback(self._binding, *args, **kwargs)
           ^^^^^^^^^^^^^^^^^^^^^^^^^^^^^^^^^^^^^^^^^^^^^^^^^^^
  File "D:\Project\Python\qpneruy-Git\music\db_refesh.py", line 33, in _on_guild_join
    cursor.execute(query)
  File "C:\Users\huuti\AppData\Local\Programs\Python\Python311\Lib\site-packages\pymysql\cursors.py", line 153, in execute
    result = self._query(query)
             ^^^^^^^^^^^^^^^^^^
  File "C:\Users\huuti\AppData\Local\Programs\Python\Python311\Lib\site-packages\pymysql\cursors.py", line 322, in _query
    conn.query(q)
  File "C:\Users\huuti\AppData\Local\Programs\Python\Python311\Lib\site-packages\pymysql\connections.py", line 558, in query
    self._affected_rows = self._read_query_result(unbuffered=unbuffered)
                          ^^^^^^^^^^^^^^^^^^^^^^^^^^^^^^^^^^^^^^^^^^^^^^
  File "C:\Users\huuti\AppData\Local\Programs\Python\Python311\Lib\site-packages\pymysql\connections.py", line 822, in _read_query_result
    result.read()
  File "C:\Users\huuti\AppData\Local\Programs\Python\Python311\Lib\site-packages\pymysql\connections.py", line 1200, in read
    first_packet = self.connection._read_packet()
                   ^^^^^^^^^^^^^^^^^^^^^^^^^^^^^^
  File "C:\Users\huuti\AppData\Local\Programs\Python\Python311\Lib\site-packages\pymysql\connections.py", line 772, in _read_packet
    packet.raise_for_error()
  File "C:\Users\huuti\AppData\Local\Programs\Python\Python311\Lib\site-packages\pymysql\protocol.py", line 221, in raise_for_error
    err.raise_mysql_exception(self._data)
  File "C:\Users\huuti\AppData\Local\Programs\Python\Python311\Lib\site-packages\pymysql\err.py", line 143, in raise_mysql_exception
    raise errorclass(errno, errval)
pymysql.err.OperationalError: (1050, "Table 'server_992122463897001994' already exists")

[18:14:05] [DEBUG] Caching ingested rate limit data for: dd84d9818020c27975c0d5ab4a794d44
[18:14:05] [DEBUG] GET /applications/{application_id}/commands Has exhausted its ratelimit (1000)! Locking route for 0.001 seconds
[18:14:05] [DEBUG] GET /applications/{application_id}/commands Received 200 :: [0/1000 calls remaining]
[18:14:05] [DEBUG] Waiting for bucket dd84d9818020c27975c0d5ab4a794d44 to unlock.
[18:14:06] [DEBUG] Caching ingested rate limit data for: dd84d9818020c27975c0d5ab4a794d44
[18:14:06] [DEBUG] GET /applications/{application_id}/commands Has exhausted its ratelimit (1000)! Locking route for 0.001 seconds
[18:14:06] [DEBUG] GET /applications/{application_id}/commands Received 200 :: [0/1000 calls remaining]
[18:14:06] [INFO] Overwriting 0 with 15 application commands
[18:14:07] [DEBUG] Caching ingested rate limit data for: 3e32a240d3716487d7d8f6dae6c54f6b
[18:14:07] [DEBUG] PUT /applications/{app_id}/commands Received 200 :: [1/2 calls remaining]
[18:14:07] [DEBUG] Sync of 1 scopes took 1.4640303999913158 seconds
[18:14:07] [DEBUG] Dispatching Event: startup
[18:14:07] [DEBUG] Sending data to websocket: {"op": 3, "d": {"since": 1702034047068, "activities": [{"name": "l\u1ec7nh /help \u0111\u1ec3 gi\u00fap \u0111\u1ee1", "type": 0}], "status": "idle", "afk": false}}
[18:14:10] [DEBUG] Sending heartbeat every 41.25 seconds
[18:14:10] [DEBUG] Sending data to websocket: {"op": 1, "d": 5}
[18:14:10] [DEBUG] Shard ID 0 | ❤ Gateway is sending a Heartbeat
[18:14:10] [DEBUG] Shard ID 0 | ❤ Received heartbeat acknowledgement from gateway
[18:14:16] [DEBUG] Dispatching Event: guild_join
[18:14:16] [DEBUG] Dispatching Event: error
[18:14:16] [ERROR] Ignoring exception in GuildJoin():
Traceback (most recent call last):
  File "C:\Users\huuti\AppData\Local\Programs\Python\Python311\Lib\site-packages\interactions\client\client.py", line 607, in _async_wrap
    await _coro(_event, *_args, **_kwargs)
  File "C:\Users\huuti\AppData\Local\Programs\Python\Python311\Lib\site-packages\interactions\models\internal\callback.py", line 31, in __call__
    return await self.callback(self._binding, *args, **kwargs)
           ^^^^^^^^^^^^^^^^^^^^^^^^^^^^^^^^^^^^^^^^^^^^^^^^^^^
  File "D:\Project\Python\qpneruy-Git\music\db_refesh.py", line 33, in _on_guild_join
    cursor.execute(query)
  File "C:\Users\huuti\AppData\Local\Programs\Python\Python311\Lib\site-packages\pymysql\cursors.py", line 153, in execute
    result = self._query(query)
             ^^^^^^^^^^^^^^^^^^
  File "C:\Users\huuti\AppData\Local\Programs\Python\Python311\Lib\site-packages\pymysql\cursors.py", line 322, in _query
    conn.query(q)
  File "C:\Users\huuti\AppData\Local\Programs\Python\Python311\Lib\site-packages\pymysql\connections.py", line 558, in query
    self._affected_rows = self._read_query_result(unbuffered=unbuffered)
                          ^^^^^^^^^^^^^^^^^^^^^^^^^^^^^^^^^^^^^^^^^^^^^^
  File "C:\Users\huuti\AppData\Local\Programs\Python\Python311\Lib\site-packages\pymysql\connections.py", line 822, in _read_query_result
    result.read()
  File "C:\Users\huuti\AppData\Local\Programs\Python\Python311\Lib\site-packages\pymysql\connections.py", line 1200, in read
    first_packet = self.connection._read_packet()
                   ^^^^^^^^^^^^^^^^^^^^^^^^^^^^^^
  File "C:\Users\huuti\AppData\Local\Programs\Python\Python311\Lib\site-packages\pymysql\connections.py", line 772, in _read_packet
    packet.raise_for_error()
  File "C:\Users\huuti\AppData\Local\Programs\Python\Python311\Lib\site-packages\pymysql\protocol.py", line 221, in raise_for_error
    err.raise_mysql_exception(self._data)
  File "C:\Users\huuti\AppData\Local\Programs\Python\Python311\Lib\site-packages\pymysql\err.py", line 143, in raise_mysql_exception
    raise errorclass(errno, errval)
pymysql.err.OperationalError: (1050, "Table 'server_1176400128232402974' already exists")

[18:14:16] [DEBUG] Dispatching Event: message_create
[18:14:24] [DEBUG] Shard ID 0 | No processor for `raw_guild_integrations_update`
[18:14:51] [DEBUG] Sending data to websocket: {"op": 1, "d": 12}
[18:14:51] [DEBUG] Shard ID 0 | ❤ Gateway is sending a Heartbeat
[18:14:52] [DEBUG] Shard ID 0 | ❤ Received heartbeat acknowledgement from gateway
[18:15:33] [DEBUG] Sending data to websocket: {"op": 1, "d": 12}
[18:15:33] [DEBUG] Shard ID 0 | ❤ Gateway is sending a Heartbeat
[18:15:33] [DEBUG] Shard ID 0 | ❤ Received heartbeat acknowledgement from gateway
[18:16:14] [DEBUG] Sending data to websocket: {"op": 1, "d": 12}
[18:16:14] [DEBUG] Shard ID 0 | ❤ Gateway is sending a Heartbeat
[18:16:14] [DEBUG] Shard ID 0 | ❤ Received heartbeat acknowledgement from gateway
[18:16:55] [DEBUG] Sending data to websocket: {"op": 1, "d": 12}
[18:16:55] [DEBUG] Shard ID 0 | ❤ Gateway is sending a Heartbeat
[18:16:55] [DEBUG] Shard ID 0 | ❤ Received heartbeat acknowledgement from gateway
[18:17:36] [DEBUG] Sending data to websocket: {"op": 1, "d": 12}
[18:17:36] [DEBUG] Shard ID 0 | ❤ Gateway is sending a Heartbeat
[18:17:37] [DEBUG] Shard ID 0 | ❤ Received heartbeat acknowledgement from gateway
[18:17:41] [DEBUG] Dispatching Event: disconnect
[18:17:41] [DEBUG] Stopping the bot.
[18:17:41] [INFO] Shard ID 0 | Stopping Shard
